File: Savefile/ReTo081126.raw
#####################################################################
###  RESONANT COLUMN/TORTIONAL SHEAR TESTING RESULTS              ###
#####################################################################
--------------------------------------------------------
  ### TESTING INFORMATION ###
--------------------------------------------------------
Project Name :
Performer :
Sample name  :
Date                : 2008/11/26 오후 1:08:13
--------------------------------------------------------
### SAMPLE DIMENSIONS & CONFINING PRESSURE ###
--------------------------------------------------------
Sample height       : 100.00 mm
Sample diameter    : 50.00 mm
Sample weight       : 300.00 g
Confining pressure : 0 kPa
--------------------------------------------------------
       ### THE SYSTEM SETTING STATUS  ###
--------------------------------------------------------
Accelerometer sensitivity                       : 0.4900 V/g
Accelerometer gain                               : X 1
Mass polar moment inertia of drive plate : 2.996E+6 g-mm2
Location of accelerometer                      : 53.000 mm
Mass polar moment inertia of topcap      : 6.198E+4 g-mm2
Twisting angle calibration factor             : 2.670E-3 rad/V
Torque calibration factor                        : 1.645E-1 mm
Low-pass filter #1 gain                          : 2.8981
Low-pass filter #2 gain                          : 0.9913
Mass polar moment inertia of target        : 1.842E+4 g-mm2
--------------------------------------------------------
File :C:\Documents and Settings\지반동역학연구실\바탕 화면\builds\Savefile\ReTo081126.raw

----------------------------------------------------------------
   ### TORTIONAL SHEAR TEST RESULTS ###
----------------------------------------------------------------
Tortional shear test_No. 1
Cell pressure : 0.0 kPa
Waveform Type is : Sine Wave
Excitation voltage : 0.10 Vp
Loading frequency : 0.50Hz
# of loading cycles : 10 cycles
Sampling rate : 75.00 Hz
----------------------------------------------------------------
----------------------------------------------------------------
### MEASURED SIGNALS OF TS TESTS ###
----------------------------------------------------------------
Column 1 : Outputs of proximitor system(V)
Column 2 : Excited voltage to coils(V)
Column 3 : Shear strain(milli-strain)
Column 4 : Shear stress(kPa)
-3.0823E-2	6.1035E-4	2.8646E-5	3.3839E-3
6.7139E-3	6.4087E-3	7.1180E-3	3.5531E-2
1.6174E-2	1.5869E-2	8.9048E-3	8.7981E-2
2.1973E-2	2.5024E-2	9.9999E-3	1.3874E-1
3.1433E-2	3.1433E-2	1.1787E-2	1.7427E-1
3.9978E-2	3.9978E-2	1.3400E-2	2.2164E-1
4.6082E-2	4.8523E-2	1.4553E-2	2.6902E-1
5.4016E-2	5.4016E-2	1.6052E-2	2.9947E-1
6.1646E-2	6.1951E-2	1.7493E-2	3.4346E-1
6.6528E-2	6.8970E-2	1.8415E-2	3.8238E-1
7.3242E-2	7.3547E-2	1.9683E-2	4.0776E-1
7.9956E-2	7.9651E-2	2.0951E-2	4.4160E-1
8.3008E-2	8.5449E-2	2.1527E-2	4.7374E-1
8.7585E-2	8.8196E-2	2.2392E-2	4.8897E-1
9.2163E-2	9.2163E-2	2.3256E-2	5.1097E-1
9.4299E-2	9.5825E-2	2.3660E-2	5.3127E-1
9.7046E-2	9.7656E-2	2.4179E-2	5.4142E-1
9.9792E-2	9.9487E-2	2.4697E-2	5.5157E-1
1.0010E-1	1.0010E-1	2.4755E-2	5.5496E-1
1.0071E-1	1.0040E-1	2.4870E-2	5.5665E-1
1.0010E-1	9.9792E-2	2.4755E-2	5.5326E-1
9.9182E-2	9.8572E-2	2.4582E-2	5.4650E-1
9.6741E-2	9.7046E-2	2.4121E-2	5.3804E-1
9.4604E-2	9.4299E-2	2.3717E-2	5.2281E-1
9.2468E-2	9.0637E-2	2.3314E-2	5.0251E-1
8.7891E-2	8.8501E-2	2.2449E-2	4.9066E-1
8.3008E-2	8.3313E-2	2.1527E-2	4.6190E-1
7.9651E-2	7.7209E-2	2.0893E-2	4.2806E-1
7.2937E-2	7.3547E-2	1.9625E-2	4.0776E-1
6.6223E-2	6.6223E-2	1.8357E-2	3.6715E-1
6.1340E-2	5.9204E-2	1.7435E-2	3.2824E-1
5.4321E-2	5.4016E-2	1.6109E-2	2.9947E-1
4.5471E-2	4.5776E-2	1.4438E-2	2.5379E-1
3.9978E-2	3.7537E-2	1.3400E-2	2.0811E-1
3.1128E-2	3.0823E-2	1.1729E-2	1.7089E-1
2.2278E-2	2.1973E-2	1.0057E-2	1.2182E-1
1.5869E-2	1.3123E-2	8.8471E-3	7.2753E-2
7.0190E-3	7.0190E-3	7.1756E-3	3.8915E-2
-2.7466E-3	-2.4414E-3	5.3313E-3	-1.3536E-2
-9.1553E-3	-1.1902E-2	4.1209E-3	-6.5986E-2
-1.8005E-2	-1.7395E-2	2.4494E-3	-9.6441E-2
-2.7161E-2	-2.7161E-2	7.2029E-4	-1.5058E-1
-3.3264E-2	-3.6316E-2	-4.3245E-4	-2.0134E-1
-4.2419E-2	-4.1809E-2	-2.1616E-3	-2.3180E-1
-5.0354E-2	-5.0354E-2	-3.6601E-3	-2.7917E-1
-5.5542E-2	-5.8289E-2	-4.6400E-3	-3.2316E-1
-6.3171E-2	-6.3477E-2	-6.0809E-3	-3.5192E-1
-7.0496E-2	-7.0190E-2	-7.4642E-3	-3.8915E-1
-7.4158E-2	-7.7209E-2	-8.1558E-3	-4.2806E-1
-8.0872E-2	-8.0566E-2	-9.4238E-3	-4.4667E-1
-8.5449E-2	-8.5754E-2	-1.0288E-2	-4.7543E-1
-8.9111E-2	-9.0332E-2	-1.0980E-2	-5.0081E-1
-9.2773E-2	-9.2468E-2	-1.1672E-2	-5.1266E-1
-9.5825E-2	-9.5215E-2	-1.2248E-2	-5.2789E-1
-9.7351E-2	-9.8267E-2	-1.2536E-2	-5.4480E-1
-9.8877E-2	-9.8877E-2	-1.2824E-2	-5.4819E-1
-9.9487E-2	-9.8877E-2	-1.2940E-2	-5.4819E-1
-9.9182E-2	-9.9182E-2	-1.2882E-2	-5.4988E-1
-9.8572E-2	-9.8877E-2	-1.2767E-2	-5.4819E-1
-9.7351E-2	-9.7656E-2	-1.2536E-2	-5.4142E-1
-9.6130E-2	-9.5215E-2	-1.2306E-2	-5.2789E-1
-9.2468E-2	-9.3079E-2	-1.1614E-2	-5.1604E-1
-8.8501E-2	-8.8806E-2	-1.0865E-2	-4.9235E-1
-8.5144E-2	-8.4229E-2	-1.0231E-2	-4.6698E-1
-7.9956E-2	-8.0566E-2	-9.2509E-3	-4.4667E-1
-7.4768E-2	-7.4768E-2	-8.2711E-3	-4.1453E-1
-6.9885E-2	-6.8054E-2	-7.3489E-3	-3.7730E-1
-6.3171E-2	-6.3477E-2	-6.0809E-3	-3.5192E-1
-5.5542E-2	-5.5542E-2	-4.6400E-3	-3.0793E-1
-5.0354E-2	-4.7607E-2	-3.6601E-3	-2.6394E-1
-4.2725E-2	-4.2419E-2	-2.2192E-3	-2.3518E-1
-3.3264E-2	-3.3569E-2	-4.3245E-4	-1.8611E-1
-2.7161E-2	-2.3804E-2	7.2029E-4	-1.3197E-1
-1.7700E-2	-1.8005E-2	2.5070E-3	-9.9824E-2
-9.1553E-3	-8.8501E-3	4.1209E-3	-4.9066E-2
-2.4414E-3	6.1035E-4	5.3889E-3	3.3839E-3
7.0190E-3	6.7139E-3	7.1756E-3	3.7223E-2
1.5869E-2	1.5869E-2	8.8471E-3	8.7981E-2
2.2278E-2	2.5024E-2	1.0057E-2	1.3874E-1
3.0823E-2	3.1128E-2	1.1671E-2	1.7258E-1
4.0588E-2	4.0283E-2	1.3516E-2	2.2334E-1
4.5776E-2	4.7913E-2	1.4496E-2	2.6563E-1
5.3711E-2	5.3711E-2	1.5994E-2	2.9778E-1
6.1646E-2	6.1340E-2	1.7493E-2	3.4008E-1
6.6223E-2	6.8970E-2	1.8357E-2	3.8238E-1
7.3547E-2	7.2937E-2	1.9741E-2	4.0437E-1
7.9041E-2	7.9346E-2	2.0778E-2	4.3990E-1
8.3008E-2	8.4839E-2	2.1527E-2	4.7036E-1
8.7891E-2	8.7891E-2	2.2449E-2	4.8728E-1
9.2468E-2	9.2163E-2	2.3314E-2	5.1097E-1
9.4604E-2	9.5825E-2	2.3717E-2	5.3127E-1
9.7046E-2	9.7046E-2	2.4179E-2	5.3804E-1
9.8877E-2	9.9487E-2	2.4524E-2	5.5157E-1
1.0010E-1	1.0040E-1	2.4755E-2	5.5665E-1
1.0101E-1	1.0071E-1	2.4928E-2	5.5834E-1
1.0010E-1	9.9487E-2	2.4755E-2	5.5157E-1
9.9182E-2	9.8877E-2	2.4582E-2	5.4819E-1
9.7351E-2	9.7656E-2	2.4236E-2	5.4142E-1
9.3689E-2	9.4299E-2	2.3545E-2	5.2281E-1
9.2468E-2	9.0332E-2	2.3314E-2	5.0081E-1
8.8196E-2	8.7891E-2	2.2507E-2	4.8728E-1
8.3008E-2	8.3313E-2	2.1527E-2	4.6190E-1
7.9651E-2	7.7515E-2	2.0893E-2	4.2975E-1
7.2937E-2	7.3853E-2	1.9625E-2	4.0945E-1
6.6833E-2	6.6833E-2	1.8473E-2	3.7053E-1
6.1035E-2	5.9204E-2	1.7377E-2	3.2824E-1
5.4016E-2	5.3711E-2	1.6052E-2	2.9778E-1
4.5776E-2	4.5776E-2	1.4496E-2	2.5379E-1
3.9978E-2	3.7537E-2	1.3400E-2	2.0811E-1
3.0823E-2	3.1433E-2	1.1671E-2	1.7427E-1
2.1973E-2	2.1973E-2	9.9999E-3	1.2182E-1
1.6174E-2	1.3428E-2	8.9048E-3	7.4445E-2
6.7139E-3	6.4087E-3	7.1180E-3	3.5531E-2
-2.1362E-3	-2.1362E-3	5.4465E-3	-1.1844E-2
-8.8501E-3	-1.1902E-2	4.1785E-3	-6.5986E-2
-1.8005E-2	-1.8616E-2	2.4494E-3	-1.0321E-1
-2.7771E-2	-2.7466E-2	6.0502E-4	-1.5227E-1
-3.2959E-2	-3.6926E-2	-3.7481E-4	-2.0472E-1
-4.2725E-2	-4.2419E-2	-2.2192E-3	-2.3518E-1
-5.0659E-2	-5.0354E-2	-3.7178E-3	-2.7917E-1
-5.5542E-2	-5.8594E-2	-4.6400E-3	-3.2485E-1
-6.2866E-2	-6.2866E-2	-6.0232E-3	-3.4854E-1
-7.0190E-2	-6.9885E-2	-7.4065E-3	-3.8745E-1
-7.4768E-2	-7.6904E-2	-8.2711E-3	-4.2637E-1
-8.0872E-2	-8.0566E-2	-9.4238E-3	-4.4667E-1
-8.5754E-2	-8.6060E-2	-1.0346E-2	-4.7713E-1
-8.8806E-2	-9.0027E-2	-1.0922E-2	-4.9912E-1
-9.3079E-2	-9.2468E-2	-1.1729E-2	-5.1266E-1
-9.5825E-2	-9.5215E-2	-1.2248E-2	-5.2789E-1
-9.7351E-2	-9.7656E-2	-1.2536E-2	-5.4142E-1
-9.8572E-2	-9.8877E-2	-1.2767E-2	-5.4819E-1
-9.9792E-2	-9.9792E-2	-1.2997E-2	-5.5326E-1
-9.9487E-2	-9.9182E-2	-1.2940E-2	-5.4988E-1
-9.8877E-2	-9.8572E-2	-1.2824E-2	-5.4650E-1
-9.7351E-2	-9.7351E-2	-1.2536E-2	-5.3973E-1
-9.5825E-2	-9.4910E-2	-1.2248E-2	-5.2619E-1
-9.2773E-2	-9.3079E-2	-1.1672E-2	-5.1604E-1
-8.8501E-2	-8.8501E-2	-1.0865E-2	-4.9066E-1
-8.5754E-2	-8.3923E-2	-1.0346E-2	-4.6528E-1
-8.0566E-2	-8.0566E-2	-9.3662E-3	-4.4667E-1
-7.4463E-2	-7.4463E-2	-8.2135E-3	-4.1283E-1
-7.0496E-2	-6.7444E-2	-7.4642E-3	-3.7392E-1
-6.3171E-2	-6.3171E-2	-6.0809E-3	-3.5023E-1
-5.5847E-2	-5.5542E-2	-4.6976E-3	-3.0793E-1
-5.0354E-2	-4.7913E-2	-3.6601E-3	-2.6563E-1
-4.3030E-2	-4.2114E-2	-2.2768E-3	-2.3349E-1
-3.3569E-2	-3.3569E-2	-4.9009E-4	-1.8611E-1
-2.7466E-2	-2.4109E-2	6.6265E-4	-1.3366E-1
-1.8616E-2	-1.7700E-2	2.3341E-3	-9.8132E-2
-8.8501E-3	-9.1553E-3	4.1785E-3	-5.0758E-2
-3.0518E-3	3.0518E-4	5.2736E-3	1.6919E-3
6.7139E-3	6.7139E-3	7.1180E-3	3.7223E-2
1.5564E-2	1.5259E-2	8.7895E-3	8.4597E-2
2.2278E-2	2.5330E-2	1.0057E-2	1.4043E-1
3.0823E-2	3.1128E-2	1.1671E-2	1.7258E-1
3.9368E-2	3.9978E-2	1.3285E-2	2.2164E-1
4.6387E-2	4.9133E-2	1.4611E-2	2.7240E-1
5.4321E-2	5.4016E-2	1.6109E-2	2.9947E-1
6.1646E-2	6.1646E-2	1.7493E-2	3.4177E-1
6.6223E-2	6.8970E-2	1.8357E-2	3.8238E-1
7.3242E-2	7.3242E-2	1.9683E-2	4.0607E-1
7.9651E-2	7.9651E-2	2.0893E-2	4.4160E-1
8.3008E-2	8.4839E-2	2.1527E-2	4.7036E-1
8.7891E-2	8.7585E-2	2.2449E-2	4.8559E-1
9.2468E-2	9.2468E-2	2.3314E-2	5.1266E-1
9.4299E-2	9.5825E-2	2.3660E-2	5.3127E-1
9.7046E-2	9.6741E-2	2.4179E-2	5.3634E-1
9.9182E-2	9.9182E-2	2.4582E-2	5.4988E-1
1.0040E-1	1.0040E-1	2.4813E-2	5.5665E-1
1.0101E-1	1.0071E-1	2.4928E-2	5.5834E-1
1.0010E-1	1.0010E-1	2.4755E-2	5.5496E-1
9.9487E-2	9.9792E-2	2.4640E-2	5.5326E-1
9.7046E-2	9.7351E-2	2.4179E-2	5.3973E-1
9.5215E-2	9.4604E-2	2.3833E-2	5.2450E-1
9.2163E-2	9.2773E-2	2.3256E-2	5.1435E-1
8.7585E-2	8.8196E-2	2.2392E-2	4.8897E-1
8.3008E-2	8.3313E-2	2.1527E-2	4.6190E-1
7.9041E-2	8.0872E-2	2.0778E-2	4.4836E-1
7.3547E-2	7.3242E-2	1.9741E-2	4.0607E-1
6.6223E-2	6.6528E-2	1.8357E-2	3.6884E-1
6.1035E-2	6.3782E-2	1.7377E-2	3.5362E-1
5.3711E-2	5.4016E-2	1.5994E-2	2.9947E-1
4.6082E-2	4.5471E-2	1.4553E-2	2.5210E-1
3.9978E-2	4.0283E-2	1.3400E-2	2.2334E-1
3.1433E-2	3.0823E-2	1.1787E-2	1.7089E-1
2.1667E-2	2.1362E-2	9.9422E-3	1.1844E-1
1.5869E-2	1.6479E-2	8.8471E-3	9.1365E-2
6.4087E-3	6.1035E-3	7.0604E-3	3.3839E-2
-2.4414E-3	-2.4414E-3	5.3889E-3	-1.3536E-2
-9.1553E-3	-8.8501E-3	4.1209E-3	-4.9066E-2
-1.8005E-2	-1.8311E-2	2.4494E-3	-1.0152E-1
-2.7161E-2	-2.7161E-2	7.2029E-4	-1.5058E-1
-3.3569E-2	-3.3569E-2	-4.9009E-4	-1.8611E-1
-4.2419E-2	-4.2114E-2	-2.1616E-3	-2.3349E-1
-5.0354E-2	-5.0964E-2	-3.6601E-3	-2.8255E-1
-5.5542E-2	-5.5847E-2	-4.6400E-3	-3.0962E-1
-6.2866E-2	-6.3171E-2	-6.0232E-3	-3.5023E-1
-7.0496E-2	-6.9885E-2	-7.4642E-3	-3.8745E-1
-7.4463E-2	-7.4158E-2	-8.2135E-3	-4.1114E-1
-8.0261E-2	-8.0261E-2	-9.3086E-3	-4.4498E-1
-8.5144E-2	-8.5754E-2	-1.0231E-2	-4.7543E-1
-8.8806E-2	-8.8806E-2	-1.0922E-2	-4.9235E-1
-9.2163E-2	-9.2773E-2	-1.1556E-2	-5.1435E-1
-9.5825E-2	-9.5215E-2	-1.2248E-2	-5.2789E-1
-9.7351E-2	-9.7351E-2	-1.2536E-2	-5.3973E-1
-9.8877E-2	-9.8877E-2	-1.2824E-2	-5.4819E-1
-9.9792E-2	-9.9182E-2	-1.2997E-2	-5.4988E-1
-9.9792E-2	-9.9487E-2	-1.2997E-2	-5.5157E-1
-9.8267E-2	-9.8572E-2	-1.2709E-2	-5.4650E-1
-9.7046E-2	-9.7656E-2	-1.2479E-2	-5.4142E-1
-9.5215E-2	-9.6130E-2	-1.2133E-2	-5.3296E-1
-9.2468E-2	-9.2773E-2	-1.1614E-2	-5.1435E-1
-8.8806E-2	-8.8806E-2	-1.0922E-2	-4.9235E-1
-8.5449E-2	-8.5449E-2	-1.0288E-2	-4.7374E-1
-8.0261E-2	-8.0566E-2	-9.3086E-3	-4.4667E-1
-7.4463E-2	-7.4768E-2	-8.2135E-3	-4.1453E-1
-6.9885E-2	-7.0496E-2	-7.3489E-3	-3.9084E-1
-6.3171E-2	-6.3171E-2	-6.0809E-3	-3.5023E-1
-5.6152E-2	-5.5542E-2	-4.7552E-3	-3.0793E-1
-5.0049E-2	-5.0049E-2	-3.6025E-3	-2.7748E-1
-4.2114E-2	-4.2419E-2	-2.1039E-3	-2.3518E-1
-3.3875E-2	-3.3875E-2	-5.4772E-4	-1.8781E-1
-2.7161E-2	-2.7466E-2	7.2029E-4	-1.5227E-1
-1.8005E-2	-1.8005E-2	2.4494E-3	-9.9824E-2
-8.8501E-3	-8.8501E-3	4.1785E-3	-4.9066E-2
-2.7466E-3	-2.1362E-3	5.3313E-3	-1.1844E-2
6.7139E-3	6.7139E-3	7.1180E-3	3.7223E-2
1.5869E-2	1.5869E-2	8.8471E-3	8.7981E-2
2.2278E-2	2.2278E-2	1.0057E-2	1.2351E-1
3.0518E-2	3.1433E-2	1.1614E-2	1.7427E-1
4.0588E-2	3.9978E-2	1.3516E-2	2.2164E-1
4.6082E-2	4.5471E-2	1.4553E-2	2.5210E-1
5.3711E-2	5.4016E-2	1.5994E-2	2.9947E-1
6.1646E-2	6.1951E-2	1.7493E-2	3.4346E-1
6.5918E-2	6.6833E-2	1.8300E-2	3.7053E-1
7.3853E-2	7.3242E-2	1.9798E-2	4.0607E-1
7.9651E-2	7.9346E-2	2.0893E-2	4.3990E-1
8.3008E-2	8.3313E-2	2.1527E-2	4.6190E-1
8.8196E-2	8.8196E-2	2.2507E-2	4.8897E-1
9.2163E-2	9.2163E-2	2.3256E-2	5.1097E-1
9.3994E-2	9.4299E-2	2.3602E-2	5.2281E-1
9.7046E-2	9.7656E-2	2.4179E-2	5.4142E-1
9.9792E-2	9.8877E-2	2.4697E-2	5.4819E-1
9.9487E-2	1.0040E-1	2.4640E-2	5.5665E-1
1.0040E-1	1.0010E-1	2.4813E-2	5.5496E-1
9.9487E-2	9.9487E-2	2.4640E-2	5.5157E-1
9.9182E-2	9.8877E-2	2.4582E-2	5.4819E-1
9.7046E-2	9.7351E-2	2.4179E-2	5.3973E-1
9.3994E-2	9.4299E-2	2.3602E-2	5.2281E-1
9.2163E-2	9.1858E-2	2.3256E-2	5.0927E-1
8.8501E-2	8.8196E-2	2.2565E-2	4.8897E-1
8.3008E-2	8.3618E-2	2.1527E-2	4.6359E-1
7.9346E-2	7.9346E-2	2.0836E-2	4.3990E-1
7.3547E-2	7.2937E-2	1.9741E-2	4.0437E-1
6.6528E-2	6.6528E-2	1.8415E-2	3.6884E-1
6.1951E-2	6.1340E-2	1.7550E-2	3.4008E-1
5.3711E-2	5.4016E-2	1.5994E-2	2.9947E-1
4.5471E-2	4.5471E-2	1.4438E-2	2.5210E-1
3.9978E-2	4.0283E-2	1.3400E-2	2.2334E-1
3.0823E-2	3.1128E-2	1.1671E-2	1.7258E-1
2.1973E-2	2.2278E-2	9.9999E-3	1.2351E-1
1.5259E-2	1.5869E-2	8.7318E-3	8.7981E-2
7.0190E-3	6.7139E-3	7.1756E-3	3.7223E-2
-2.4414E-3	-2.7466E-3	5.3889E-3	-1.5227E-2
-8.5449E-3	-8.5449E-3	4.2362E-3	-4.7374E-2
-1.8311E-2	-1.7395E-2	2.3918E-3	-9.6441E-2
-2.7771E-2	-2.7466E-2	6.0502E-4	-1.5227E-1
-3.3264E-2	-3.3569E-2	-4.3245E-4	-1.8611E-1
-4.1809E-2	-4.2114E-2	-2.0463E-3	-2.3349E-1
-5.0659E-2	-5.0354E-2	-3.7178E-3	-2.7917E-1
-5.5237E-2	-5.5542E-2	-4.5823E-3	-3.0793E-1
-6.3171E-2	-6.3171E-2	-6.0809E-3	-3.5023E-1
-7.0190E-2	-7.0190E-2	-7.4065E-3	-3.8915E-1
-7.4768E-2	-7.4768E-2	-8.2711E-3	-4.1453E-1
-8.0261E-2	-8.0261E-2	-9.3086E-3	-4.4498E-1
-8.5754E-2	-8.5144E-2	-1.0346E-2	-4.7205E-1
-8.8501E-2	-8.8806E-2	-1.0865E-2	-4.9235E-1
-9.2773E-2	-9.2773E-2	-1.1672E-2	-5.1435E-1
-9.5520E-2	-9.6130E-2	-1.2190E-2	-5.3296E-1
-9.7046E-2	-9.7351E-2	-1.2479E-2	-5.3973E-1
-9.9182E-2	-9.9182E-2	-1.2882E-2	-5.4988E-1
-9.9487E-2	-9.9792E-2	-1.2940E-2	-5.5326E-1
-9.9487E-2	-9.9182E-2	-1.2940E-2	-5.4988E-1
-9.8877E-2	-9.8572E-2	-1.2824E-2	-5.4650E-1
-9.7046E-2	-9.7351E-2	-1.2479E-2	-5.3973E-1
-9.6130E-2	-9.5825E-2	-1.2306E-2	-5.3127E-1
-9.3079E-2	-9.2468E-2	-1.1729E-2	-5.1266E-1
-8.8501E-2	-8.8501E-2	-1.0865E-2	-4.9066E-1
-8.5449E-2	-8.6060E-2	-1.0288E-2	-4.7713E-1
-8.0566E-2	-8.0872E-2	-9.3662E-3	-4.4836E-1
-7.4158E-2	-7.4463E-2	-8.1558E-3	-4.1283E-1
-7.0190E-2	-6.9885E-2	-7.4065E-3	-3.8745E-1
-6.3477E-2	-6.2866E-2	-6.1385E-3	-3.4854E-1
-5.5847E-2	-5.5847E-2	-4.6976E-3	-3.0962E-1
-5.0659E-2	-5.0354E-2	-3.7178E-3	-2.7917E-1
-4.2419E-2	-4.2419E-2	-2.1616E-3	-2.3518E-1
-3.3569E-2	-3.3569E-2	-4.9009E-4	-1.8611E-1
-2.6855E-2	-2.7161E-2	7.7793E-4	-1.5058E-1
-1.8616E-2	-1.8311E-2	2.3341E-3	-1.0152E-1
-8.5449E-3	-8.8501E-3	4.2362E-3	-4.9066E-2
-2.7466E-3	-3.0518E-3	5.3313E-3	-1.6919E-2
6.7139E-3	7.0190E-3	7.1180E-3	3.8915E-2
1.5869E-2	1.5564E-2	8.8471E-3	8.6289E-2
2.2583E-2	2.2278E-2	1.0115E-2	1.2351E-1
3.1128E-2	3.1433E-2	1.1729E-2	1.7427E-1
3.9978E-2	3.9978E-2	1.3400E-2	2.2164E-1
4.6082E-2	4.5166E-2	1.4553E-2	2.5041E-1
5.4016E-2	5.3406E-2	1.6052E-2	2.9609E-1
6.1340E-2	6.1646E-2	1.7435E-2	3.4177E-1
6.6223E-2	6.7139E-2	1.8357E-2	3.7223E-1
7.3242E-2	7.3547E-2	1.9683E-2	4.0776E-1
7.9346E-2	7.9651E-2	2.0836E-2	4.4160E-1
8.3313E-2	8.3313E-2	2.1585E-2	4.6190E-1
8.8196E-2	8.8196E-2	2.2507E-2	4.8897E-1
9.2163E-2	9.2468E-2	2.3256E-2	5.1266E-1
9.4299E-2	9.4604E-2	2.3660E-2	5.2450E-1
9.7351E-2	9.7046E-2	2.4236E-2	5.3804E-1
9.9182E-2	9.8877E-2	2.4582E-2	5.4819E-1
9.9792E-2	1.0010E-1	2.4697E-2	5.5496E-1
1.0040E-1	1.0071E-1	2.4813E-2	5.5834E-1
9.9792E-2	9.9792E-2	2.4697E-2	5.5326E-1
9.9487E-2	9.9487E-2	2.4640E-2	5.5157E-1
9.7351E-2	9.7656E-2	2.4236E-2	5.4142E-1
9.3689E-2	9.4604E-2	2.3545E-2	5.2450E-1
9.2468E-2	9.2163E-2	2.3314E-2	5.1097E-1
8.7891E-2	8.7891E-2	2.2449E-2	4.8728E-1
8.2703E-2	8.3313E-2	2.1470E-2	4.6190E-1
7.9346E-2	7.9346E-2	2.0836E-2	4.3990E-1
7.3242E-2	7.2937E-2	1.9683E-2	4.0437E-1
6.6223E-2	6.6223E-2	1.8357E-2	3.6715E-1
6.1951E-2	6.1340E-2	1.7550E-2	3.4008E-1
5.4016E-2	5.4321E-2	1.6052E-2	3.0117E-1
4.5776E-2	4.5776E-2	1.4496E-2	2.5379E-1
4.0283E-2	3.9978E-2	1.3458E-2	2.2164E-1
3.0823E-2	3.1128E-2	1.1671E-2	1.7258E-1
2.1973E-2	2.1973E-2	9.9999E-3	1.2182E-1
1.5869E-2	1.5564E-2	8.8471E-3	8.6289E-2
7.0190E-3	6.7139E-3	7.1756E-3	3.7223E-2
-1.8311E-3	-2.4414E-3	5.5042E-3	-1.3536E-2
-8.8501E-3	-9.4604E-3	4.1785E-3	-5.2450E-2
-1.8005E-2	-1.8005E-2	2.4494E-3	-9.9824E-2
-2.7466E-2	-2.7771E-2	6.6265E-4	-1.5397E-1
-3.2959E-2	-3.3569E-2	-3.7481E-4	-1.8611E-1
-4.2725E-2	-4.2725E-2	-2.2192E-3	-2.3687E-1
-5.0964E-2	-5.0354E-2	-3.7754E-3	-2.7917E-1
-5.5237E-2	-5.5542E-2	-4.5823E-3	-3.0793E-1
-6.3477E-2	-6.3171E-2	-6.1385E-3	-3.5023E-1
-7.0190E-2	-7.0190E-2	-7.4065E-3	-3.8915E-1
-7.4768E-2	-7.5073E-2	-8.2711E-3	-4.1622E-1
-8.0566E-2	-8.0261E-2	-9.3662E-3	-4.4498E-1
-8.5449E-2	-8.5754E-2	-1.0288E-2	-4.7543E-1
-8.8501E-2	-8.8806E-2	-1.0865E-2	-4.9235E-1
-9.2773E-2	-9.2773E-2	-1.1672E-2	-5.1435E-1
-9.5825E-2	-9.5825E-2	-1.2248E-2	-5.3127E-1
-9.7351E-2	-9.7046E-2	-1.2536E-2	-5.3804E-1
-9.8267E-2	-9.8572E-2	-1.2709E-2	-5.4650E-1
-9.9792E-2	-9.8877E-2	-1.2997E-2	-5.4819E-1
-9.9487E-2	-9.9792E-2	-1.2940E-2	-5.5326E-1
-9.8572E-2	-9.8572E-2	-1.2767E-2	-5.4650E-1
-9.7351E-2	-9.7046E-2	-1.2536E-2	-5.3804E-1
-9.5215E-2	-9.5520E-2	-1.2133E-2	-5.2958E-1
-9.2773E-2	-9.2468E-2	-1.1672E-2	-5.1266E-1
-8.8501E-2	-8.8806E-2	-1.0865E-2	-4.9235E-1
-8.6060E-2	-8.5144E-2	-1.0404E-2	-4.7205E-1
-8.0261E-2	-8.0566E-2	-9.3086E-3	-4.4667E-1
-7.4768E-2	-7.4463E-2	-8.2711E-3	-4.1283E-1
-7.0190E-2	-7.0801E-2	-7.4065E-3	-3.9253E-1
-6.3477E-2	-6.3171E-2	-6.1385E-3	-3.5023E-1
-5.5542E-2	-5.5237E-2	-4.6400E-3	-3.0624E-1
-5.0659E-2	-5.0659E-2	-3.7178E-3	-2.8086E-1
-4.2419E-2	-4.2114E-2	-2.1616E-3	-2.3349E-1
-3.3569E-2	-3.3569E-2	-4.9009E-4	-1.8611E-1
-2.7161E-2	-2.7466E-2	7.2029E-4	-1.5227E-1
-1.8311E-2	-1.8311E-2	2.3918E-3	-1.0152E-1
-8.8501E-3	-8.8501E-3	4.1785E-3	-4.9066E-2
-2.7466E-3	-2.4414E-3	5.3313E-3	-1.3536E-2
7.0190E-3	7.0190E-3	7.1756E-3	3.8915E-2
1.5869E-2	1.5564E-2	8.8471E-3	8.6289E-2
2.2278E-2	2.1667E-2	1.0057E-2	1.2013E-1
3.0823E-2	3.1738E-2	1.1671E-2	1.7596E-1
4.0283E-2	3.9978E-2	1.3458E-2	2.2164E-1
4.5776E-2	4.5776E-2	1.4496E-2	2.5379E-1
5.3711E-2	5.4321E-2	1.5994E-2	3.0117E-1
6.1951E-2	6.1646E-2	1.7550E-2	3.4177E-1
6.6833E-2	6.5918E-2	1.8473E-2	3.6546E-1
7.2937E-2	7.3242E-2	1.9625E-2	4.0607E-1
7.9956E-2	7.9346E-2	2.0951E-2	4.3990E-1
8.3008E-2	8.3008E-2	2.1527E-2	4.6021E-1
8.8196E-2	8.8501E-2	2.2507E-2	4.9066E-1
9.2468E-2	9.2468E-2	2.3314E-2	5.1266E-1
9.4604E-2	9.4299E-2	2.3717E-2	5.2281E-1
9.6741E-2	9.7656E-2	2.4121E-2	5.4142E-1
9.9182E-2	9.8877E-2	2.4582E-2	5.4819E-1
1.0010E-1	9.9792E-2	2.4755E-2	5.5326E-1
1.0040E-1	1.0010E-1	2.4813E-2	5.5496E-1
9.9792E-2	9.9487E-2	2.4697E-2	5.5157E-1
9.9487E-2	9.9182E-2	2.4640E-2	5.4988E-1
9.7351E-2	9.7351E-2	2.4236E-2	5.3973E-1
9.4299E-2	9.4604E-2	2.3660E-2	5.2450E-1
9.1858E-2	9.1858E-2	2.3199E-2	5.0927E-1
8.7585E-2	8.8196E-2	2.2392E-2	4.8897E-1
8.2703E-2	8.3313E-2	2.1470E-2	4.6190E-1
7.9651E-2	7.9651E-2	2.0893E-2	4.4160E-1
7.2937E-2	7.3242E-2	1.9625E-2	4.0607E-1
6.6528E-2	6.6528E-2	1.8415E-2	3.6884E-1
6.1951E-2	6.1340E-2	1.7550E-2	3.4008E-1
5.4321E-2	5.3711E-2	1.6109E-2	2.9778E-1
4.6082E-2	4.6082E-2	1.4553E-2	2.5548E-1
3.9978E-2	4.0283E-2	1.3400E-2	2.2334E-1
3.1128E-2	3.0518E-2	1.1729E-2	1.6919E-1
2.1973E-2	2.1973E-2	9.9999E-3	1.2182E-1
1.5869E-2	1.5259E-2	8.8471E-3	8.4597E-2
7.3242E-3	6.7139E-3	7.2333E-3	3.7223E-2
-2.4414E-3	-3.0518E-3	5.3889E-3	-1.6919E-2
-8.8501E-3	-8.8501E-3	4.1785E-3	-4.9066E-2
-1.8005E-2	-1.8311E-2	2.4494E-3	-1.0152E-1
-2.7466E-2	-2.7466E-2	6.6265E-4	-1.5227E-1
-3.3875E-2	-3.3264E-2	-5.4772E-4	-1.8442E-1
-4.1809E-2	-4.2114E-2	-2.0463E-3	-2.3349E-1
-5.0354E-2	-5.0049E-2	-3.6601E-3	-2.7748E-1
-5.5542E-2	-5.5847E-2	-4.6400E-3	-3.0962E-1
-6.3171E-2	-6.3477E-2	-6.0809E-3	-3.5192E-1
-7.0190E-2	-7.0496E-2	-7.4065E-3	-3.9084E-1
-7.4158E-2	-7.4463E-2	-8.1558E-3	-4.1283E-1
-8.0566E-2	-8.0566E-2	-9.3662E-3	-4.4667E-1
-8.5449E-2	-8.5754E-2	-1.0288E-2	-4.7543E-1
-8.8806E-2	-8.9111E-2	-1.0922E-2	-4.9405E-1
-9.3079E-2	-9.2468E-2	-1.1729E-2	-5.1266E-1
-9.5825E-2	-9.5825E-2	-1.2248E-2	-5.3127E-1
-9.6741E-2	-9.7351E-2	-1.2421E-2	-5.3973E-1
-9.8572E-2	-9.8877E-2	-1.2767E-2	-5.4819E-1
-9.9792E-2	-9.9487E-2	-1.2997E-2	-5.5157E-1
-9.9792E-2	-1.0010E-1	-1.2997E-2	-5.5496E-1
-9.8877E-2	-9.8572E-2	-1.2824E-2	-5.4650E-1
-9.7351E-2	-9.7351E-2	-1.2536E-2	-5.3973E-1
-9.5520E-2	-9.5825E-2	-1.2190E-2	-5.3127E-1
-9.2773E-2	-9.3079E-2	-1.1672E-2	-5.1604E-1
-8.9111E-2	-8.8806E-2	-1.0980E-2	-4.9235E-1
-8.5754E-2	-8.6365E-2	-1.0346E-2	-4.7882E-1
-8.0566E-2	-8.0566E-2	-9.3662E-3	-4.4667E-1
-7.4158E-2	-7.4463E-2	-8.1558E-3	-4.1283E-1
-7.0190E-2	-7.0801E-2	-7.4065E-3	-3.9253E-1
-6.2866E-2	-6.3477E-2	-6.0232E-3	-3.5192E-1
-5.5847E-2	-5.5542E-2	-4.6976E-3	-3.0793E-1
-5.1270E-2	-5.0354E-2	-3.8330E-3	-2.7917E-1
-4.2114E-2	-4.2725E-2	-2.1039E-3	-2.3687E-1
-3.3875E-2	-3.3569E-2	-5.4772E-4	-1.8611E-1
-2.7466E-2	-2.7161E-2	6.6265E-4	-1.5058E-1
-1.7700E-2	-1.8005E-2	2.5070E-3	-9.9824E-2
-8.8501E-3	-9.1553E-3	4.1785E-3	-5.0758E-2
-2.4414E-3	-2.4414E-3	5.3889E-3	-1.3536E-2
7.0190E-3	6.7139E-3	7.1756E-3	3.7223E-2
1.6174E-2	1.5869E-2	8.9048E-3	8.7981E-2
2.1973E-2	2.2583E-2	9.9999E-3	1.2520E-1
3.1128E-2	3.0823E-2	1.1729E-2	1.7089E-1
3.9673E-2	3.9978E-2	1.3343E-2	2.2164E-1
4.5776E-2	4.5471E-2	1.4496E-2	2.5210E-1
5.4932E-2	5.4016E-2	1.6225E-2	2.9947E-1
6.1646E-2	6.1340E-2	1.7493E-2	3.4008E-1
6.6833E-2	6.6528E-2	1.8473E-2	3.6884E-1
7.3242E-2	7.3242E-2	1.9683E-2	4.0607E-1
7.9651E-2	7.9651E-2	2.0893E-2	4.4160E-1
8.3008E-2	8.3008E-2	2.1527E-2	4.6021E-1
8.7585E-2	8.8196E-2	2.2392E-2	4.8897E-1
9.2468E-2	9.2163E-2	2.3314E-2	5.1097E-1
9.4299E-2	9.4299E-2	2.3660E-2	5.2281E-1
9.7351E-2	9.7046E-2	2.4236E-2	5.3804E-1
9.9487E-2	9.9487E-2	2.4640E-2	5.5157E-1
1.0071E-1	9.9792E-2	2.4870E-2	5.5326E-1
9.9792E-2	1.0071E-1	2.4697E-2	5.5834E-1
9.9792E-2	1.0010E-1	2.4697E-2	5.5496E-1
9.9487E-2	9.9487E-2	2.4640E-2	5.5157E-1
9.7656E-2	9.7351E-2	2.4294E-2	5.3973E-1
9.4299E-2	9.4299E-2	2.3660E-2	5.2281E-1
9.2468E-2	9.2163E-2	2.3314E-2	5.1097E-1
8.7891E-2	8.7585E-2	2.2449E-2	4.8559E-1
8.3008E-2	8.3008E-2	2.1527E-2	4.6021E-1
7.9651E-2	7.9956E-2	2.0893E-2	4.4329E-1
7.3853E-2	7.3242E-2	1.9798E-2	4.0607E-1
6.6528E-2	6.6833E-2	1.8415E-2	3.7053E-1
6.1951E-2	6.1340E-2	1.7550E-2	3.4008E-1
5.4016E-2	5.4016E-2	1.6052E-2	2.9947E-1
4.5776E-2	4.5776E-2	1.4496E-2	2.5379E-1
4.0283E-2	4.0283E-2	1.3458E-2	2.2334E-1
3.1128E-2	3.1128E-2	1.1729E-2	1.7258E-1
2.1667E-2	2.1667E-2	9.9422E-3	1.2013E-1
1.5564E-2	1.6174E-2	8.7895E-3	8.9673E-2
6.7139E-3	7.0190E-3	7.1180E-3	3.8915E-2
-2.4414E-3	-2.1362E-3	5.3889E-3	-1.1844E-2
-8.8501E-3	-8.5449E-3	4.1785E-3	-4.7374E-2
-1.7700E-2	-1.8005E-2	2.5070E-3	-9.9824E-2
-2.7466E-2	-2.6550E-2	6.6265E-4	-1.4720E-1
-3.3569E-2	-3.3569E-2	-4.9009E-4	-1.8611E-1
-4.2419E-2	-4.2419E-2	-2.1616E-3	-2.3518E-1
-5.0354E-2	-5.0964E-2	-3.6601E-3	-2.8255E-1
-5.5542E-2	-5.5542E-2	-4.6400E-3	-3.0793E-1
-6.2866E-2	-6.3171E-2	-6.0232E-3	-3.5023E-1
-7.0190E-2	-7.0801E-2	-7.4065E-3	-3.9253E-1
-7.4768E-2	-7.4768E-2	-8.2711E-3	-4.1453E-1
-8.0566E-2	-8.0566E-2	-9.3662E-3	-4.4667E-1
-8.5754E-2	-8.5754E-2	-1.0346E-2	-4.7543E-1
-8.9111E-2	-8.9417E-2	-1.0980E-2	-4.9574E-1
-9.2773E-2	-9.2468E-2	-1.1672E-2	-5.1266E-1
-9.6130E-2	-9.5825E-2	-1.2306E-2	-5.3127E-1
-9.7351E-2	-9.7656E-2	-1.2536E-2	-5.4142E-1
-9.8572E-2	-9.8572E-2	-1.2767E-2	-5.4650E-1
-9.9792E-2	-9.9487E-2	-1.2997E-2	-5.5157E-1
-9.9792E-2	-9.9792E-2	-1.2997E-2	-5.5326E-1
-9.8877E-2	-9.8572E-2	-1.2824E-2	-5.4650E-1
-9.7351E-2	-9.7046E-2	-1.2536E-2	-5.3804E-1
-9.5520E-2	-9.5215E-2	-1.2190E-2	-5.2789E-1
-9.2468E-2	-9.3079E-2	-1.1614E-2	-5.1604E-1
-8.8196E-2	-8.8501E-2	-1.0807E-2	-4.9066E-1
-8.5754E-2	-8.5449E-2	-1.0346E-2	-4.7374E-1
-8.0261E-2	-8.0566E-2	-9.3086E-3	-4.4667E-1
-7.4768E-2	-7.4768E-2	-8.2711E-3	-4.1453E-1
-7.0496E-2	-7.0801E-2	-7.4642E-3	-3.9253E-1
-6.3477E-2	-6.3782E-2	-6.1385E-3	-3.5362E-1
-5.5847E-2	-5.5542E-2	-4.6976E-3	-3.0793E-1
-5.0354E-2	-5.0964E-2	-3.6601E-3	-2.8255E-1
-4.2419E-2	-4.2114E-2	-2.1616E-3	-2.3349E-1
-3.3875E-2	-3.3875E-2	-5.4772E-4	-1.8781E-1
-2.6855E-2	-2.7466E-2	7.7793E-4	-1.5227E-1
-1.8005E-2	-1.8005E-2	2.4494E-3	-9.9824E-2
-8.8501E-3	-8.8501E-3	4.1785E-3	-4.9066E-2
-2.1362E-3	-3.0518E-3	5.4465E-3	-1.6919E-2
6.7139E-3	6.7139E-3	7.1180E-3	3.7223E-2
1.6174E-2	1.6174E-2	8.9048E-3	8.9673E-2
2.1973E-2	2.2278E-2	9.9999E-3	1.2351E-1
3.1128E-2	3.0212E-2	1.1729E-2	1.6750E-1
3.9368E-2	4.0283E-2	1.3285E-2	2.2334E-1
4.5776E-2	4.5776E-2	1.4496E-2	2.5379E-1
5.4626E-2	5.4321E-2	1.6167E-2	3.0117E-1
6.1646E-2	6.1951E-2	1.7493E-2	3.4346E-1
6.6528E-2	6.6833E-2	1.8415E-2	3.7053E-1
7.3242E-2	7.3547E-2	1.9683E-2	4.0776E-1
7.9346E-2	7.9956E-2	2.0836E-2	4.4329E-1
8.3313E-2	8.3008E-2	2.1585E-2	4.6021E-1
8.8501E-2	8.8501E-2	2.2565E-2	4.9066E-1
9.2468E-2	9.1553E-2	2.3314E-2	5.0758E-1
9.4604E-2	9.4604E-2	2.3717E-2	5.2450E-1
9.7046E-2	9.7656E-2	2.4179E-2	5.4142E-1
9.9182E-2	9.9487E-2	2.4582E-2	5.5157E-1
9.9792E-2	9.9792E-2	2.4697E-2	5.5326E-1
1.0010E-1	1.0040E-1	2.4755E-2	5.5665E-1
9.9792E-2	1.0010E-1	2.4697E-2	5.5496E-1
9.9487E-2	9.8877E-2	2.4640E-2	5.4819E-1
9.7046E-2	9.7046E-2	2.4179E-2	5.3804E-1
9.4299E-2	9.4299E-2	2.3660E-2	5.2281E-1
9.2773E-2	9.2468E-2	2.3372E-2	5.1266E-1
8.8501E-2	8.8501E-2	2.2565E-2	4.9066E-1
8.3313E-2	8.3313E-2	2.1585E-2	4.6190E-1
7.9651E-2	7.9651E-2	2.0893E-2	4.4160E-1
7.3242E-2	7.3547E-2	1.9683E-2	4.0776E-1
6.6528E-2	6.6528E-2	1.8415E-2	3.6884E-1
6.1951E-2	6.1646E-2	1.7550E-2	3.4177E-1
5.4016E-2	5.4321E-2	1.6052E-2	3.0117E-1
4.5776E-2	4.5776E-2	1.4496E-2	2.5379E-1
4.0283E-2	4.0283E-2	1.3458E-2	2.2334E-1
3.1433E-2	3.0823E-2	1.1787E-2	1.7089E-1
2.2278E-2	2.2278E-2	1.0057E-2	1.2351E-1
1.6174E-2	1.6174E-2	8.9048E-3	8.9673E-2
6.7139E-3	6.4087E-3	7.1180E-3	3.5531E-2
-2.1362E-3	-2.4414E-3	5.4465E-3	-1.3536E-2
-8.8501E-3	-8.8501E-3	4.1785E-3	-4.9066E-2
-1.7700E-2	-1.8311E-2	2.5070E-3	-1.0152E-1
-2.7161E-2	-2.7161E-2	7.2029E-4	-1.5058E-1
-3.3264E-2	-3.3569E-2	-4.3245E-4	-1.8611E-1
-4.1809E-2	-4.1809E-2	-2.0463E-3	-2.3180E-1
-5.0354E-2	-5.0659E-2	-3.6601E-3	-2.8086E-1
-5.5847E-2	-5.5847E-2	-4.6976E-3	-3.0962E-1
-6.2561E-2	-6.3477E-2	-5.9656E-3	-3.5192E-1
-7.0190E-2	-7.0190E-2	-7.4065E-3	-3.8915E-1
-7.4463E-2	-7.4463E-2	-8.2135E-3	-4.1283E-1
-8.0261E-2	-8.0261E-2	-9.3086E-3	-4.4498E-1
-8.5449E-2	-8.5754E-2	-1.0288E-2	-4.7543E-1
-8.8806E-2	-8.8501E-2	-1.0922E-2	-4.9066E-1
-9.2773E-2	-9.2773E-2	-1.1672E-2	-5.1435E-1
-9.5520E-2	-9.5215E-2	-1.2190E-2	-5.2789E-1
-9.7046E-2	-9.7351E-2	-1.2479E-2	-5.3973E-1
-9.8877E-2	-9.8877E-2	-1.2824E-2	-5.4819E-1
-9.9182E-2	-9.9792E-2	-1.2882E-2	-5.5326E-1
-9.9792E-2	-9.9487E-2	-1.2997E-2	-5.5157E-1
-9.8572E-2	-9.9182E-2	-1.2767E-2	-5.4988E-1
-9.7351E-2	-9.7351E-2	-1.2536E-2	-5.3973E-1
-9.5825E-2	-9.5825E-2	-1.2248E-2	-5.3127E-1
-9.2468E-2	-9.2773E-2	-1.1614E-2	-5.1435E-1
-8.8501E-2	-8.8501E-2	-1.0865E-2	-4.9066E-1
-8.5144E-2	-8.5754E-2	-1.0231E-2	-4.7543E-1
-8.0566E-2	-7.9956E-2	-9.3662E-3	-4.4329E-1
-7.4768E-2	-7.4463E-2	-8.2711E-3	-4.1283E-1
-7.0190E-2	-7.0190E-2	-7.4065E-3	-3.8915E-1
-6.3171E-2	-6.3477E-2	-6.0809E-3	-3.5192E-1
-5.5542E-2	-5.5847E-2	-4.6400E-3	-3.0962E-1
-5.0049E-2	-5.0354E-2	-3.6025E-3	-2.7917E-1
-4.1809E-2	-4.2114E-2	-2.0463E-3	-2.3349E-1
-3.3569E-2	-3.2959E-2	-4.9009E-4	-1.8273E-1
-2.7161E-2	-2.7466E-2	7.2029E-4	-1.5227E-1
-1.8311E-2	-1.8311E-2	2.3918E-3	-1.0152E-1
-8.8501E-3	-9.1553E-3	4.1785E-3	-5.0758E-2
-2.1362E-3	-3.0518E-3	5.4465E-3	-1.6919E-2
7.3242E-3	7.0190E-3	7.2333E-3	3.8915E-2
1.6174E-2	1.5869E-2	8.9048E-3	8.7981E-2
2.1973E-2	2.2583E-2	9.9999E-3	1.2520E-1
3.1128E-2	3.1738E-2	1.1729E-2	1.7596E-1
4.0283E-2	3.9978E-2	1.3458E-2	2.2164E-1
4.5471E-2	4.6082E-2	1.4438E-2	2.5548E-1
5.3711E-2	5.4321E-2	1.5994E-2	3.0117E-1
6.2256E-2	6.1951E-2	1.7608E-2	3.4346E-1
6.7139E-2	6.6833E-2	1.8530E-2	3.7053E-1
7.3242E-2	7.2937E-2	1.9683E-2	4.0437E-1
7.9041E-2	7.9651E-2	2.0778E-2	4.4160E-1
8.3313E-2	8.3313E-2	2.1585E-2	4.6190E-1
8.7891E-2	8.7891E-2	2.2449E-2	4.8728E-1
9.2163E-2	9.2468E-2	2.3256E-2	5.1266E-1
9.4299E-2	9.4299E-2	2.3660E-2	5.2281E-1
9.6436E-2	9.7351E-2	2.4063E-2	5.3973E-1
9.9182E-2	9.9487E-2	2.4582E-2	5.5157E-1
9.9792E-2	9.9792E-2	2.4697E-2	5.5326E-1
1.0071E-1	1.0071E-1	2.4870E-2	5.5834E-1
1.0010E-1	9.9792E-2	2.4755E-2	5.5326E-1
9.9487E-2	9.9487E-2	2.4640E-2	5.5157E-1
9.6741E-2	9.7351E-2	2.4121E-2	5.3973E-1
9.4604E-2	9.4299E-2	2.3717E-2	5.2281E-1
9.2773E-2	9.2163E-2	2.3372E-2	5.1097E-1
8.8196E-2	8.7891E-2	2.2507E-2	4.8728E-1
8.3008E-2	8.3313E-2	2.1527E-2	4.6190E-1
7.9346E-2	7.9651E-2	2.0836E-2	4.4160E-1
7.2937E-2	7.2937E-2	1.9625E-2	4.0437E-1
6.6528E-2	6.7139E-2	1.8415E-2	3.7223E-1
6.1951E-2	6.1646E-2	1.7550E-2	3.4177E-1
5.4016E-2	5.4321E-2	1.6052E-2	3.0117E-1
4.6082E-2	4.6082E-2	1.4553E-2	2.5548E-1
4.0283E-2	4.0588E-2	1.3458E-2	2.2503E-1
3.1128E-2	3.1433E-2	1.1729E-2	1.7427E-1
2.2278E-2	2.1973E-2	1.0057E-2	1.2182E-1
1.5869E-2	1.5869E-2	8.8471E-3	8.7981E-2
7.0190E-3	7.0190E-3	7.1756E-3	3.8915E-2
-2.4414E-3	-2.7466E-3	5.3889E-3	-1.5227E-2
-9.1553E-3	-8.8501E-3	4.1209E-3	-4.9066E-2
-1.8311E-2	-1.8616E-2	2.3918E-3	-1.0321E-1
-2.6855E-2	-2.7161E-2	7.7793E-4	-1.5058E-1
-3.3569E-2	-3.3569E-2	-4.9009E-4	-1.8611E-1
-4.2419E-2	-4.1809E-2	-2.1616E-3	-2.3180E-1
-5.0354E-2	-5.0659E-2	-3.6601E-3	-2.8086E-1
-5.5542E-2	-5.5542E-2	-4.6400E-3	-3.0793E-1
-6.3171E-2	-6.3477E-2	-6.0809E-3	-3.5192E-1
-6.9580E-2	-7.0190E-2	-7.2913E-3	-3.8915E-1
-7.4463E-2	-7.4158E-2	-8.2135E-3	-4.1114E-1
-8.0566E-2	-7.9956E-2	-9.3662E-3	-4.4329E-1
-8.5144E-2	-8.5449E-2	-1.0231E-2	-4.7374E-1
-8.8806E-2	-8.9111E-2	-1.0922E-2	-4.9405E-1
-9.2773E-2	-9.2468E-2	-1.1672E-2	-5.1266E-1
-9.5825E-2	-9.5520E-2	-1.2248E-2	-5.2958E-1
-9.7351E-2	-9.7351E-2	-1.2536E-2	-5.3973E-1
-9.8877E-2	-9.8572E-2	-1.2824E-2	-5.4650E-1
-9.9792E-2	-9.9487E-2	-1.2997E-2	-5.5157E-1
-9.9487E-2	-9.9792E-2	-1.2940E-2	-5.5326E-1
-9.8572E-2	-9.8877E-2	-1.2767E-2	-5.4819E-1
-9.7351E-2	-9.7351E-2	-1.2536E-2	-5.3973E-1
-9.5520E-2	-9.5825E-2	-1.2190E-2	-5.3127E-1
-9.2468E-2	-9.2468E-2	-1.1614E-2	-5.1266E-1
-8.8501E-2	-8.8806E-2	-1.0865E-2	-4.9235E-1
-8.5144E-2	-8.5754E-2	-1.0231E-2	-4.7543E-1
-8.0872E-2	-8.0566E-2	-9.4238E-3	-4.4667E-1
-7.4463E-2	-7.4768E-2	-8.2135E-3	-4.1453E-1
-6.9885E-2	-7.0496E-2	-7.3489E-3	-3.9084E-1
-6.3477E-2	-6.2866E-2	-6.1385E-3	-3.4854E-1
-5.5237E-2	-5.5237E-2	-4.5823E-3	-3.0624E-1
-5.0354E-2	-5.0354E-2	-3.6601E-3	-2.7917E-1
-4.2419E-2	-4.2419E-2	-2.1616E-3	-2.3518E-1
-3.2959E-2	-3.2959E-2	-3.7481E-4	-1.8273E-1
-2.7466E-2	-2.7466E-2	6.6265E-4	-1.5227E-1
-1.8311E-2	-1.8311E-2	2.3918E-3	-1.0152E-1
-8.8501E-3	-9.1553E-3	4.1785E-3	-5.0758E-2
-2.4414E-3	-2.7466E-3	5.3889E-3	-1.5227E-2
6.4087E-3	7.0190E-3	7.0604E-3	3.8915E-2
1.6174E-2	1.6174E-2	8.9048E-3	8.9673E-2
2.1973E-2	2.2278E-2	9.9999E-3	1.2351E-1
3.1128E-2	3.1128E-2	1.1729E-2	1.7258E-1
3.9673E-2	3.9978E-2	1.3343E-2	2.2164E-1
4.6082E-2	4.5471E-2	1.4553E-2	2.5210E-1
5.4016E-2	5.3711E-2	1.6052E-2	2.9778E-1
6.1340E-2	6.1340E-2	1.7435E-2	3.4008E-1
6.6528E-2	6.6528E-2	1.8415E-2	3.6884E-1
7.3547E-2	7.3547E-2	1.9741E-2	4.0776E-1
7.9346E-2	7.9346E-2	2.0836E-2	4.3990E-1
8.3008E-2	8.3008E-2	2.1527E-2	4.6021E-1
8.7585E-2	8.7891E-2	2.2392E-2	4.8728E-1
9.2163E-2	9.2163E-2	2.3256E-2	5.1097E-1
9.4299E-2	9.3994E-2	2.3660E-2	5.2112E-1
9.6741E-2	9.7351E-2	2.4121E-2	5.3973E-1
9.9182E-2	9.8877E-2	2.4582E-2	5.4819E-1
9.9792E-2	9.9792E-2	2.4697E-2	5.5326E-1
1.0071E-1	1.0071E-1	2.4870E-2	5.5834E-1
1.0010E-1	9.9792E-2	2.4755E-2	5.5326E-1
9.9487E-2	9.9487E-2	2.4640E-2	5.5157E-1
9.7656E-2	9.7046E-2	2.4294E-2	5.3804E-1
9.4604E-2	9.3994E-2	2.3717E-2	5.2112E-1
9.2468E-2	9.2163E-2	2.3314E-2	5.1097E-1
8.8196E-2	8.8196E-2	2.2507E-2	4.8897E-1
8.3313E-2	8.3008E-2	2.1585E-2	4.6021E-1
7.9651E-2	7.9346E-2	2.0893E-2	4.3990E-1
7.2937E-2	7.3242E-2	1.9625E-2	4.0607E-1
6.6223E-2	6.6833E-2	1.8357E-2	3.7053E-1
6.2561E-2	6.1646E-2	1.7666E-2	3.4177E-1
5.4016E-2	5.3711E-2	1.6052E-2	2.9778E-1
4.5776E-2	4.5776E-2	1.4496E-2	2.5379E-1
3.9673E-2	3.9978E-2	1.3343E-2	2.2164E-1
3.1128E-2	3.1128E-2	1.1729E-2	1.7258E-1
2.2278E-2	2.2278E-2	1.0057E-2	1.2351E-1
1.5869E-2	1.5564E-2	8.8471E-3	8.6289E-2
7.0190E-3	7.0190E-3	7.1756E-3	3.8915E-2
-2.4414E-3	-2.7466E-3	5.3889E-3	-1.5227E-2
-8.5449E-3	-9.4604E-3	4.2362E-3	-5.2450E-2
-1.8311E-2	-1.8005E-2	2.3918E-3	-9.9824E-2
-2.7161E-2	-2.7161E-2	7.2029E-4	-1.5058E-1
-3.2959E-2	-3.3264E-2	-3.7481E-4	-1.8442E-1
-4.1809E-2	-4.2419E-2	-2.0463E-3	-2.3518E-1
-5.0964E-2	-5.0964E-2	-3.7754E-3	-2.8255E-1
-5.5237E-2	-5.5847E-2	-4.5823E-3	-3.0962E-1
-6.3477E-2	-6.3477E-2	-6.1385E-3	-3.5192E-1
-6.9885E-2	-7.0190E-2	-7.3489E-3	-3.8915E-1
-7.4463E-2	-7.4768E-2	-8.2135E-3	-4.1453E-1
-7.9956E-2	-8.0566E-2	-9.2509E-3	-4.4667E-1
-8.6060E-2	-8.5449E-2	-1.0404E-2	-4.7374E-1
-8.8196E-2	-8.8806E-2	-1.0807E-2	-4.9235E-1
-9.2468E-2	-9.2468E-2	-1.1614E-2	-5.1266E-1
-9.6130E-2	-9.5520E-2	-1.2306E-2	-5.2958E-1
-9.7351E-2	-9.7351E-2	-1.2536E-2	-5.3973E-1
-9.8572E-2	-9.8572E-2	-1.2767E-2	-5.4650E-1
-9.9487E-2	-1.0010E-1	-1.2940E-2	-5.5496E-1
-9.9792E-2	-9.9487E-2	-1.2997E-2	-5.5157E-1
-9.8572E-2	-9.8572E-2	-1.2767E-2	-5.4650E-1
-9.6741E-2	-9.7046E-2	-1.2421E-2	-5.3804E-1
-9.5825E-2	-9.5825E-2	-1.2248E-2	-5.3127E-1
-9.2773E-2	-9.2468E-2	-1.1672E-2	-5.1266E-1
-8.8501E-2	-8.8806E-2	-1.0865E-2	-4.9235E-1
-8.5754E-2	-8.5754E-2	-1.0346E-2	-4.7543E-1
-8.0566E-2	-8.0261E-2	-9.3662E-3	-4.4498E-1
-7.4463E-2	-7.4768E-2	-8.2135E-3	-4.1453E-1
-7.0190E-2	-6.9885E-2	-7.4065E-3	-3.8745E-1
-6.2866E-2	-6.3477E-2	-6.0232E-3	-3.5192E-1
-5.6152E-2	-5.5542E-2	-4.7552E-3	-3.0793E-1
-5.0659E-2	-5.0659E-2	-3.7178E-3	-2.8086E-1
-4.2419E-2	-4.2419E-2	-2.1616E-3	-2.3518E-1
-3.3875E-2	-3.3264E-2	-5.4772E-4	-1.8442E-1
-2.7466E-2	-2.6855E-2	6.6265E-4	-1.4889E-1
-1.8005E-2	-1.8005E-2	2.4494E-3	-9.9824E-2
-8.8501E-3	-9.1553E-3	4.1785E-3	-5.0758E-2
-2.7466E-3	-2.4414E-3	5.3313E-3	-1.3536E-2
-2.4414E-3	-2.7466E-3	5.3889E-3	-1.5227E-2
-2.7466E-3	-2.4414E-3	5.3313E-3	-1.3536E-2
-2.4414E-3	-2.7466E-3	5.3889E-3	-1.5227E-2
-2.4414E-3	-2.4414E-3	5.3889E-3	-1.3536E-2
-2.4414E-3	-2.1362E-3	5.3889E-3	-1.1844E-2
-2.7466E-3	-2.4414E-3	5.3313E-3	-1.3536E-2
-2.7466E-3	-2.7466E-3	5.3313E-3	-1.5227E-2
-2.4414E-3	-2.7466E-3	5.3889E-3	-1.5227E-2
-2.4414E-3	-2.1362E-3	5.3889E-3	-1.1844E-2
-2.7466E-3	-2.4414E-3	5.3313E-3	-1.3536E-2
-3.0518E-3	-2.4414E-3	5.2736E-3	-1.3536E-2
-2.7466E-3	-1.8311E-3	5.3313E-3	-1.0152E-2
-2.7466E-3	-2.4414E-3	5.3313E-3	-1.3536E-2
-2.7466E-3	-2.4414E-3	5.3313E-3	-1.3536E-2
-3.0518E-3	-2.7466E-3	5.2736E-3	-1.5227E-2
-2.4414E-3	-2.4414E-3	5.3889E-3	-1.3536E-2
-2.4414E-3	-2.7466E-3	5.3889E-3	-1.5227E-2
-3.0518E-3	-2.1362E-3	5.2736E-3	-1.1844E-2
-2.4414E-3	-2.4414E-3	5.3889E-3	-1.3536E-2
-2.4414E-3	-2.7466E-3	5.3889E-3	-1.5227E-2
-2.4414E-3	-2.4414E-3	5.3889E-3	-1.3536E-2
-2.7466E-3	-2.4414E-3	5.3313E-3	-1.3536E-2
-2.4414E-3	-2.1362E-3	5.3889E-3	-1.1844E-2
-2.4414E-3	-3.0518E-3	5.3889E-3	-1.6919E-2
-2.7466E-3	-2.4414E-3	5.3313E-3	-1.3536E-2
-2.4414E-3	-2.7466E-3	5.3889E-3	-1.5227E-2
-2.4414E-3	-2.7466E-3	5.3889E-3	-1.5227E-2
-2.7466E-3	-2.4414E-3	5.3313E-3	-1.3536E-2
-3.0518E-3	-2.7466E-3	5.2736E-3	-1.5227E-2
-2.7466E-3	-3.3569E-3	5.3313E-3	-1.8611E-2
-3.3569E-3	-2.4414E-3	5.2160E-3	-1.3536E-2
-2.4414E-3	-2.4414E-3	5.3889E-3	-1.3536E-2
-2.4414E-3	-2.7466E-3	5.3889E-3	-1.5227E-2
-3.0518E-3	-2.4414E-3	5.2736E-3	-1.3536E-2
-2.4414E-3	-1.8311E-3	5.3889E-3	-1.0152E-2
-2.4414E-3	-2.4414E-3	5.3889E-3	-1.3536E-2
-2.7466E-3	-2.4414E-3	5.3313E-3	-1.3536E-2
-2.7466E-3	-2.1362E-3	5.3313E-3	-1.1844E-2
-3.3569E-3	-2.4414E-3	5.2160E-3	-1.3536E-2
-2.7466E-3	-2.4414E-3	5.3313E-3	-1.3536E-2
-2.7466E-3	-2.7466E-3	5.3313E-3	-1.5227E-2
-2.4414E-3	-2.7466E-3	5.3889E-3	-1.5227E-2
-2.4414E-3	-2.4414E-3	5.3889E-3	-1.3536E-2
-2.1362E-3	-2.4414E-3	5.4465E-3	-1.3536E-2
-2.4414E-3	-3.0518E-3	5.3889E-3	-1.6919E-2
-2.7466E-3	-2.7466E-3	5.3313E-3	-1.5227E-2
-2.4414E-3	-3.0518E-3	5.3889E-3	-1.6919E-2
-2.4414E-3	-2.4414E-3	5.3889E-3	-1.3536E-2
-2.7466E-3	-2.4414E-3	5.3313E-3	-1.3536E-2
-2.4414E-3	-2.4414E-3	5.3889E-3	-1.3536E-2
-2.7466E-3	-3.0518E-3	5.3313E-3	-1.6919E-2
-2.7466E-3	-2.7466E-3	5.3313E-3	-1.5227E-2
-2.4414E-3	-2.4414E-3	5.3889E-3	-1.3536E-2
-2.7466E-3	-3.0518E-3	5.3313E-3	-1.6919E-2
-2.7466E-3	-2.4414E-3	5.3313E-3	-1.3536E-2
-2.4414E-3	-2.4414E-3	5.3889E-3	-1.3536E-2
-2.1362E-3	-2.4414E-3	5.4465E-3	-1.3536E-2
-2.4414E-3	-2.4414E-3	5.3889E-3	-1.3536E-2
-3.0518E-3	-2.4414E-3	5.2736E-3	-1.3536E-2
-2.4414E-3	-2.7466E-3	5.3889E-3	-1.5227E-2
-2.4414E-3	-2.4414E-3	5.3889E-3	-1.3536E-2
-3.0518E-3	-2.7466E-3	5.2736E-3	-1.5227E-2
-2.7466E-3	-3.0518E-3	5.3313E-3	-1.6919E-2
-2.7466E-3	-2.1362E-3	5.3313E-3	-1.1844E-2
-2.4414E-3	-2.7466E-3	5.3889E-3	-1.5227E-2
-2.4414E-3	-2.7466E-3	5.3889E-3	-1.5227E-2
-2.7466E-3	-2.4414E-3	5.3313E-3	-1.3536E-2
-2.1362E-3	-2.4414E-3	5.4465E-3	-1.3536E-2
-2.4414E-3	-3.0518E-3	5.3889E-3	-1.6919E-2
-2.4414E-3	-2.4414E-3	5.3889E-3	-1.3536E-2
-2.7466E-3	-2.7466E-3	5.3313E-3	-1.5227E-2
-2.1362E-3	-2.7466E-3	5.4465E-3	-1.5227E-2
-2.4414E-3	-2.7466E-3	5.3889E-3	-1.5227E-2
-2.4414E-3	-2.4414E-3	5.3889E-3	-1.3536E-2
-1.8311E-3	-2.4414E-3	5.5042E-3	-1.3536E-2

----------------------------------------------------------------
   ### TORTIONAL SHEAR TEST RESULTS ###
----------------------------------------------------------------
Tortional shear test_No. 2
Cell pressure : 0.0 kPa
Waveform Type is : Sine Wave
Excitation voltage : 0.10 Vp
Loading frequency : 0.50Hz
# of loading cycles : 50 cycles
Sampling rate : 75.00 Hz
----------------------------------------------------------------
----------------------------------------------------------------
### MEASURED SIGNALS OF TS TESTS ###
----------------------------------------------------------------
Column 1 : Outputs of proximitor system(V)
Column 2 : Excited voltage to coils(V)
Column 3 : Shear strain(milli-strain)
Column 4 : Shear stress(kPa)
-2.4414E-3	3.0518E-4	2.7089E-5	1.6919E-3
2.7771E-2	2.8076E-2	5.7332E-3	1.5566E-1
5.4321E-2	5.4016E-2	1.0748E-2	2.9947E-1
7.5378E-2	7.7209E-2	1.4725E-2	4.2806E-1
9.2468E-2	9.2163E-2	1.7952E-2	5.1097E-1
9.9487E-2	9.9487E-2	1.9278E-2	5.5157E-1
9.9182E-2	9.8572E-2	1.9220E-2	5.4650E-1
8.9111E-2	8.9722E-2	1.7318E-2	4.9743E-1
7.2937E-2	7.2937E-2	1.4263E-2	4.0437E-1
5.1575E-2	4.8523E-2	1.0229E-2	2.6902E-1
2.2278E-2	2.1667E-2	4.6957E-3	1.2013E-1
-6.4087E-3	-5.7983E-3	-7.2219E-4	-3.2147E-2
-3.3875E-2	-3.6316E-2	-5.9095E-3	-2.0134E-1
-6.1646E-2	-6.0730E-2	-1.1155E-2	-3.3670E-1
-8.0566E-2	-8.0872E-2	-1.4728E-2	-4.4836E-1
-9.3079E-2	-9.4910E-2	-1.7091E-2	-5.2619E-1
-1.0040E-1	-9.9792E-2	-1.8474E-2	-5.5326E-1
-9.5825E-2	-9.6741E-2	-1.7610E-2	-5.3634E-1
-8.5449E-2	-8.4534E-2	-1.5650E-2	-4.6867E-1
-6.5918E-2	-6.5918E-2	-1.1961E-2	-3.6546E-1
-4.2725E-2	-4.1809E-2	-7.5810E-3	-2.3180E-1
-1.4343E-2	-1.1902E-2	-2.2208E-3	-6.5986E-2
1.5564E-2	1.5869E-2	3.4277E-3	8.7981E-2
4.2419E-2	4.3030E-2	8.4997E-3	2.3856E-1
6.6528E-2	6.8970E-2	1.3053E-2	3.8238E-1
8.6060E-2	8.6670E-2	1.6742E-2	4.8051E-1
9.7351E-2	9.7046E-2	1.8874E-2	5.3804E-1
1.0040E-1	1.0010E-1	1.9451E-2	5.5496E-1
9.4299E-2	9.4604E-2	1.8298E-2	5.2450E-1
8.1787E-2	8.0872E-2	1.5935E-2	4.4836E-1
6.1646E-2	5.9204E-2	1.2131E-2	3.2824E-1
3.4790E-2	3.4485E-2	7.0588E-3	1.9119E-1
7.0190E-3	7.0190E-3	1.8138E-3	3.8915E-2
-2.1362E-2	-2.4414E-2	-3.5464E-3	-1.3536E-1
-5.0354E-2	-5.0354E-2	-9.0219E-3	-2.7917E-1
-7.2327E-2	-7.2327E-2	-1.3172E-2	-4.0099E-1
-8.8806E-2	-9.0027E-2	-1.6284E-2	-4.9912E-1
-9.8572E-2	-9.8877E-2	-1.8129E-2	-5.4819E-1
-9.8877E-2	-9.9182E-2	-1.8186E-2	-5.4988E-1
-9.2163E-2	-9.0027E-2	-1.6918E-2	-4.9912E-1
-7.4463E-2	-7.4463E-2	-1.3575E-2	-4.1283E-1
-5.3101E-2	-5.2795E-2	-9.5407E-3	-2.9271E-1
-2.6855E-2	-2.4109E-2	-4.5839E-3	-1.3366E-1
3.6621E-3	3.3569E-3	1.1798E-3	1.8611E-2
3.0823E-2	3.1433E-2	6.3095E-3	1.7427E-1
5.6152E-2	5.9204E-2	1.1093E-2	3.2824E-1
7.9346E-2	7.9346E-2	1.5474E-2	4.3990E-1
9.3689E-2	9.3384E-2	1.8183E-2	5.1773E-1
9.9792E-2	1.0040E-1	1.9336E-2	5.5665E-1
9.8267E-2	9.8267E-2	1.9047E-2	5.4480E-1
8.7891E-2	8.7585E-2	1.7088E-2	4.8559E-1
7.1411E-2	7.2327E-2	1.3975E-2	4.0099E-1
[...]
8.7677E-1	8.8623E-1	1.6608E-1	4.9134E+0
9.9640E-1	9.9518E-1	1.8867E-1	5.5174E+0
7.8430E-1	7.7057E-1	1.4862E-1	4.2721E+0
3.0975E-1	2.8900E-1	5.8991E-2	1.6023E+0
-2.6855E-1	-2.8809E-1	-5.0231E-2	-1.5972E+0
-7.5684E-1	-7.6996E-1	-1.4245E-1	-4.2688E+0
-9.9182E-1	-9.9426E-1	-1.8683E-1	-5.5123E+0
-8.9569E-1	-8.8562E-1	-1.6868E-1	-4.9100E+0
-4.9896E-1	-4.8157E-1	-9.3747E-2	-2.6699E+0
6.3477E-2	8.3923E-2	1.2478E-2	4.6528E-1
6.0516E-1	6.2073E-1	1.1478E-1	3.4414E+0
9.4513E-1	9.5154E-1	1.7899E-1	5.2755E+0
9.6863E-1	9.6375E-1	1.8343E-1	5.3431E+0
6.6956E-1	6.5399E-1	1.2695E-1	3.6258E+0
1.4648E-1	1.2573E-1	2.8155E-2	6.9708E-1
-4.2542E-1	-4.4403E-1	-7.9857E-2	-2.4618E+0
-8.5480E-1	-8.6548E-1	-1.6095E-1	-4.7983E+0
-9.9792E-1	-9.9762E-1	-1.8798E-1	-5.5309E+0
-8.0841E-1	-7.9559E-1	-1.5219E-1	-4.4109E+0
-3.4851E-1	-3.2867E-1	-6.5332E-2	-1.8222E+0
2.2827E-1	2.4902E-1	4.3602E-2	1.3806E+0
7.2998E-1	7.4371E-1	1.3836E-1	4.1233E+0
9.8633E-1	9.8969E-1	1.8677E-1	5.4870E+0
9.1370E-1	9.0515E-1	1.7305E-1	5.0183E+0
5.3589E-1	5.1819E-1	1.0170E-1	2.8729E+0
-2.1057E-2	-4.0588E-2	-3.4875E-3	-2.2503E-1
-5.7037E-1	-5.8716E-1	-1.0723E-1	-3.2553E+0
-9.2957E-1	-9.3658E-1	-1.7507E-1	-5.1926E+0
-9.7748E-1	-9.7382E-1	-1.8412E-1	-5.3990E+0
-6.9916E-1	-6.8451E-1	-1.3156E-1	-3.7950E+0
-1.8707E-1	-1.6602E-1	-3.4842E-2	-9.2042E-1
3.8818E-1	4.0680E-1	7.3804E-2	2.2554E+0
8.3282E-1	8.4503E-1	1.5778E-1	4.6850E+0
1.0007E+0	9.9976E-1	1.8948E-1	5.5428E+0
8.3282E-1	8.2153E-1	1.5778E-1	4.5547E+0
3.8727E-1	3.6865E-1	7.3631E-2	2.0439E+0
-1.8707E-1	-2.0752E-1	-3.4842E-2	-1.1505E+0
-6.9977E-1	-7.1411E-1	-1.3167E-1	-3.9591E+0
-9.7748E-1	-9.8175E-1	-1.8412E-1	-5.4430E+0
-9.2987E-1	-9.2194E-1	-1.7513E-1	-5.1113E+0
-5.7068E-1	-5.5237E-1	-1.0729E-1	-3.0624E+0
-2.0752E-2	0.0000E+0	-3.4299E-3	0.0000E+0
5.3589E-1	5.5420E-1	1.0170E-1	3.0726E+0
9.1400E-1	9.2224E-1	1.7311E-1	5.1130E+0
9.8602E-1	9.8236E-1	1.8671E-1	5.4464E+0
7.2968E-1	7.1411E-1	1.3830E-1	3.9591E+0
2.2858E-1	2.0782E-1	4.3660E-2	1.1522E+0
-3.4821E-1	-3.6743E-1	-6.5274E-2	-2.0371E+0
-8.0872E-1	-8.2092E-1	-1.5225E-1	-4.5513E+0
-9.9854E-1	-1.0001E+0	-1.8810E-1	-5.5445E+0
-8.5480E-1	-8.4412E-1	-1.6095E-1	-4.6799E+0
-4.2572E-1	-4.0649E-1	-7.9914E-2	-2.2537E+0
1.4618E-1	1.6663E-1	2.8098E-2	9.2380E-1
6.6986E-1	6.8481E-1	1.2700E-1	3.7967E+0
9.6893E-1	9.7412E-1	1.8349E-1	5.4007E+0
9.4513E-1	9.3750E-1	1.7899E-1	5.1976E+0
6.0516E-1	5.8807E-1	1.1478E-1	3.2604E+0
6.3171E-2	4.2114E-2	1.2420E-2	2.3349E-1
-4.9988E-1	-5.1758E-1	-9.3920E-2	-2.8695E+0
-8.9508E-1	-9.0454E-1	-1.6856E-1	-5.0149E+0
-9.9182E-1	-9.8877E-1	-1.8683E-1	-5.4819E+0
-7.5684E-1	-7.4280E-1	-1.4245E-1	-4.1182E+0
-2.6825E-1	-2.4872E-1	-5.0174E-2	-1.3789E+0
3.0945E-1	3.2928E-1	5.8933E-2	1.8256E+0
7.8400E-1	7.9651E-1	1.4856E-1	4.4160E+0
9.9731E-1	9.9823E-1	1.8885E-1	5.5343E+0
8.7616E-1	8.6670E-1	1.6597E-1	4.8051E+0
4.6417E-1	4.4495E-1	8.8155E-2	2.4668E+0
-1.0437E-1	-1.2512E-1	-1.9222E-2	-6.9370E-1
-6.3721E-1	-6.5277E-1	-1.1986E-1	-3.6191E+0
-9.5764E-1	-9.6313E-1	-1.8038E-1	-5.3398E+0
-9.5703E-1	-9.5032E-1	-1.8026E-1	-5.2687E+0
-6.3721E-1	-6.2073E-1	-1.1986E-1	-3.4414E+0
-1.0437E-1	-8.3313E-2	-1.9222E-2	-4.6190E-1
4.6387E-1	4.8218E-1	8.8098E-2	2.6733E+0
8.7646E-1	8.8654E-1	1.6602E-1	4.9151E+0
9.9731E-1	9.9457E-1	1.8885E-1	5.5140E+0
7.8369E-1	7.7118E-1	1.4850E-1	4.2755E+0
3.0914E-1	2.8931E-1	5.8876E-2	1.6040E+0
-2.6794E-1	-2.8900E-1	-5.0116E-2	-1.6023E+0
-7.5684E-1	-7.6996E-1	-1.4245E-1	-4.2688E+0
-9.9152E-1	-9.9426E-1	-1.8677E-1	-5.5123E+0
-8.9508E-1	-8.8562E-1	-1.6856E-1	-4.9100E+0
-4.9896E-1	-4.8126E-1	-9.3747E-2	-2.6682E+0
6.3477E-2	8.4229E-2	1.2478E-2	4.6698E-1
6.0486E-1	6.2134E-1	1.1473E-1	3.4448E+0
9.4513E-1	9.5123E-1	1.7899E-1	5.2738E+0
9.6893E-1	9.6344E-1	1.8349E-1	5.3415E+0
6.6956E-1	6.5399E-1	1.2695E-1	3.6258E+0
1.4618E-1	1.2573E-1	2.8098E-2	6.9708E-1
-4.2572E-1	-4.4403E-1	-7.9914E-2	-2.4618E+0
-8.5449E-1	-8.6578E-1	-1.6089E-1	-4.8000E+0
-9.9915E-1	-9.9792E-1	-1.8821E-1	-5.5326E+0
-8.0841E-1	-7.9590E-1	-1.5219E-1	-4.4126E+0
-3.4851E-1	-3.2837E-1	-6.5332E-2	-1.8205E+0
2.2827E-1	2.4872E-1	4.3602E-2	1.3789E+0
7.2968E-1	7.4341E-1	1.3830E-1	4.1216E+0
9.8602E-1	9.8969E-1	1.8671E-1	5.4870E+0
9.1431E-1	9.0485E-1	1.7317E-1	5.0166E+0
5.3619E-1	5.1788E-1	1.0176E-1	2.8712E+0
-2.0752E-2	-4.1504E-2	-3.4299E-3	-2.3010E-1
-5.7037E-1	-5.8746E-1	-1.0723E-1	-3.2570E+0
-9.2896E-1	-9.3658E-1	-1.7496E-1	-5.1926E+0
-9.7748E-1	-9.7321E-1	-1.8412E-1	-5.3956E+0
-6.9946E-1	-6.8420E-1	-1.3161E-1	-3.7933E+0
-1.8677E-1	-1.6602E-1	-3.4784E-2	-9.2042E-1
3.8818E-1	4.0710E-1	7.3804E-2	2.2570E+0
8.3313E-1	8.4503E-1	1.5784E-1	4.6850E+0
1.0007E+0	9.9976E-1	1.8948E-1	5.5428E+0
8.3252E-1	8.2184E-1	1.5772E-1	4.5564E+0
3.8727E-1	3.6926E-1	7.3631E-2	2.0472E+0
-1.8677E-1	-2.0752E-1	-3.4784E-2	-1.1505E+0
-7.0007E-1	-7.1411E-1	-1.3173E-1	-3.9591E+0
-9.7778E-1	-9.8175E-1	-1.8418E-1	-5.4430E+0
-9.2926E-1	-9.2163E-1	-1.7502E-1	-5.1097E+0
-5.7068E-1	-5.5298E-1	-1.0729E-1	-3.0658E+0
-2.0752E-2	3.0518E-4	-3.4299E-3	1.6919E-3
5.3650E-1	5.5359E-1	1.0182E-1	3.0692E+0
9.1400E-1	9.2224E-1	1.7311E-1	5.1130E+0
9.8633E-1	9.8297E-1	1.8677E-1	5.4497E+0
7.2937E-1	7.1472E-1	1.3824E-1	3.9625E+0
2.2797E-1	2.0844E-1	4.3544E-2	1.1556E+0
-3.4790E-1	-3.6713E-1	-6.5217E-2	-2.0354E+0
-8.0841E-1	-8.2031E-1	-1.5219E-1	-4.5479E+0
-9.9884E-1	-9.9884E-1	-1.8816E-1	-5.5377E+0
-8.5510E-1	-8.4381E-1	-1.6101E-1	-4.6782E+0
-4.2542E-1	-4.0649E-1	-7.9857E-2	-2.2537E+0
1.4679E-1	1.6663E-1	2.8213E-2	9.2380E-1
6.7017E-1	6.8451E-1	1.2706E-1	3.7950E+0
9.6924E-1	9.7412E-1	1.8354E-1	5.4007E+0
9.4452E-1	9.3719E-1	1.7888E-1	5.1959E+0
6.0486E-1	5.8868E-1	1.1473E-1	3.2638E+0
6.3171E-2	4.2114E-2	1.2420E-2	2.3349E-1
-4.9988E-1	-5.1758E-1	-9.3920E-2	-2.8695E+0
-8.9508E-1	-9.0454E-1	-1.6856E-1	-5.0149E+0
-9.9152E-1	-9.8907E-1	-1.8677E-1	-5.4836E+0
-7.5623E-1	-7.4280E-1	-1.4234E-1	-4.1182E+0
-2.6825E-1	-2.4780E-1	-5.0174E-2	-1.3739E+0
3.0945E-1	3.2928E-1	5.8933E-2	1.8256E+0
7.8400E-1	7.9681E-1	1.4856E-1	4.4177E+0
9.9640E-1	9.9792E-1	1.8867E-1	5.5326E+0
8.7677E-1	8.6639E-1	1.6608E-1	4.8034E+0
4.6387E-1	4.4525E-1	8.8098E-2	2.4685E+0
-1.0406E-1	-1.2512E-1	-1.9165E-2	-6.9370E-1
-6.3690E-1	-6.5338E-1	-1.1980E-1	-3.6224E+0
-9.5673E-1	-9.6252E-1	-1.8020E-1	-5.3364E+0
-9.5703E-1	-9.5093E-1	-1.8026E-1	-5.2721E+0
-6.3751E-1	-6.2042E-1	-1.1991E-1	-3.4397E+0
-1.0406E-1	-8.3618E-2	-1.9165E-2	-4.6359E-1
4.6356E-1	4.8248E-1	8.8040E-2	2.6750E+0
8.7646E-1	8.8654E-1	1.6602E-1	4.9151E+0
9.9670E-1	9.9457E-1	1.8873E-1	5.5140E+0
7.8369E-1	7.7087E-1	1.4850E-1	4.2738E+0
3.0975E-1	2.8931E-1	5.8991E-2	1.6040E+0
-2.6855E-1	-2.8870E-1	-5.0231E-2	-1.6006E+0
-7.5745E-1	-7.7026E-1	-1.4257E-1	-4.2705E+0
-9.9152E-1	-9.9487E-1	-1.8677E-1	-5.5157E+0
-8.9539E-1	-8.8593E-1	-1.6862E-1	-4.9117E+0
-4.9927E-1	-4.8126E-1	-9.3805E-2	-2.6682E+0
6.3171E-2	8.4534E-2	1.2420E-2	4.6867E-1
6.0455E-1	6.2164E-1	1.1467E-1	3.4465E+0
9.4482E-1	9.5123E-1	1.7893E-1	5.2738E+0
9.6954E-1	9.6344E-1	1.8360E-1	5.3415E+0
6.6986E-1	6.5399E-1	1.2700E-1	3.6258E+0
1.4679E-1	1.2573E-1	2.8213E-2	6.9708E-1
-4.2542E-1	-4.4434E-1	-7.9857E-2	-2.4635E+0
-8.5480E-1	-8.6548E-1	-1.6095E-1	-4.7983E+0
-9.9884E-1	-9.9762E-1	-1.8816E-1	-5.5309E+0
-8.0872E-1	-7.9559E-1	-1.5225E-1	-4.4109E+0
-3.4851E-1	-3.2867E-1	-6.5332E-2	-1.8222E+0
2.2858E-1	2.4872E-1	4.3660E-2	1.3789E+0
7.2968E-1	7.4341E-1	1.3830E-1	4.1216E+0
9.8602E-1	9.8969E-1	1.8671E-1	5.4870E+0
9.1370E-1	9.0515E-1	1.7305E-1	5.0183E+0
5.3589E-1	5.1819E-1	1.0170E-1	2.8729E+0
-2.0142E-2	-4.1504E-2	-3.3146E-3	-2.3010E-1
-5.7037E-1	-5.8777E-1	-1.0723E-1	-3.2587E+0
-9.2957E-1	-9.3628E-1	-1.7507E-1	-5.1909E+0
-9.7809E-1	-9.7351E-1	-1.8424E-1	-5.3973E+0
-6.9885E-1	-6.8420E-1	-1.3150E-1	-3.7933E+0
-1.8738E-1	-1.6632E-1	-3.4900E-2	-9.2211E-1
3.8788E-1	4.0649E-1	7.3746E-2	2.2537E+0
8.3313E-1	8.4412E-1	1.5784E-1	4.6799E+0
9.9976E-1	9.9976E-1	1.8931E-1	5.5428E+0
8.3344E-1	8.2092E-1	1.5790E-1	4.5513E+0
3.8757E-1	3.6835E-1	7.3689E-2	2.0422E+0
-1.8738E-1	-2.0752E-1	-3.4900E-2	-1.1505E+0
-6.9916E-1	-7.1381E-1	-1.3156E-1	-3.9574E+0
-9.7748E-1	-9.8175E-1	-1.8412E-1	-5.4430E+0
-9.2926E-1	-9.2163E-1	-1.7502E-1	-5.1097E+0
-5.7037E-1	-5.5328E-1	-1.0723E-1	-3.0675E+0
-2.0447E-2	6.1035E-4	-3.3722E-3	3.3839E-3
5.3680E-1	5.5359E-1	1.0187E-1	3.0692E+0
9.1431E-1	9.2224E-1	1.7317E-1	5.1130E+0
9.8633E-1	9.8358E-1	1.8677E-1	5.4531E+0
7.2906E-1	7.1442E-1	1.3818E-1	3.9608E+0
2.2827E-1	2.0813E-1	4.3602E-2	1.1539E+0
-3.4790E-1	-3.6774E-1	-6.5217E-2	-2.0388E+0
-8.0872E-1	-8.2092E-1	-1.5225E-1	-4.5513E+0
-9.9854E-1	-9.9945E-1	-1.8810E-1	-5.5411E+0
-8.5510E-1	-8.4442E-1	-1.6101E-1	-4.6816E+0
-4.2572E-1	-4.0710E-1	-7.9914E-2	-2.2570E+0
1.4679E-1	1.6663E-1	2.8213E-2	9.2380E-1
6.6986E-1	6.8481E-1	1.2700E-1	3.7967E+0
9.6832E-1	9.7351E-1	1.8337E-1	5.3973E+0
9.4482E-1	9.3781E-1	1.7893E-1	5.1993E+0
6.0455E-1	5.8777E-1	1.1467E-1	3.2587E+0
6.2866E-2	4.2114E-2	1.2363E-2	2.3349E-1
-4.9957E-1	-5.1758E-1	-9.3862E-2	-2.8695E+0
-8.9569E-1	-9.0454E-1	-1.6868E-1	-5.0149E+0
-9.9182E-1	-9.8907E-1	-1.8683E-1	-5.4836E+0
-7.5653E-1	-7.4280E-1	-1.4239E-1	-4.1182E+0
-2.6855E-1	-2.4841E-1	-5.0231E-2	-1.3772E+0
3.0945E-1	3.2898E-1	5.8933E-2	1.8239E+0
7.8369E-1	7.9651E-1	1.4850E-1	4.4160E+0
9.9640E-1	9.9854E-1	1.8867E-1	5.5360E+0
8.7646E-1	8.6639E-1	1.6602E-1	4.8034E+0
4.6356E-1	4.4464E-1	8.8040E-2	2.4652E+0
-1.0437E-1	-1.2512E-1	-1.9222E-2	-6.9370E-1
-6.3721E-1	-6.5277E-1	-1.1986E-1	-3.6191E+0
-9.5642E-1	-9.6252E-1	-1.8015E-1	-5.3364E+0
-9.5703E-1	-9.5062E-1	-1.8026E-1	-5.2704E+0
-6.3690E-1	-6.2042E-1	-1.1980E-1	-3.4397E+0
-1.0406E-1	-8.3618E-2	-1.9165E-2	-4.6359E-1
4.6326E-1	4.8187E-1	8.7983E-2	2.6716E+0
8.7585E-1	8.8623E-1	1.6591E-1	4.9134E+0
9.9701E-1	9.9457E-1	1.8879E-1	5.5140E+0
7.8430E-1	7.7057E-1	1.4862E-1	4.2721E+0
3.0884E-1	2.8931E-1	5.8818E-2	1.6040E+0
-2.6855E-1	-2.8900E-1	-5.0231E-2	-1.6023E+0
-7.5653E-1	-7.6996E-1	-1.4239E-1	-4.2688E+0
-9.9182E-1	-9.9396E-1	-1.8683E-1	-5.5106E+0
-8.9478E-1	-8.8623E-1	-1.6850E-1	-4.9134E+0
-4.9927E-1	-4.8157E-1	-9.3805E-2	-2.6699E+0
6.3171E-2	8.3618E-2	1.2420E-2	4.6359E-1
6.0455E-1	6.2164E-1	1.1467E-1	3.4465E+0
9.4452E-1	9.5123E-1	1.7888E-1	5.2738E+0
9.6893E-1	9.6375E-1	1.8349E-1	5.3431E+0
6.6956E-1	6.5369E-1	1.2695E-1	3.6241E+0
1.4679E-1	1.2604E-1	2.8213E-2	6.9877E-1
-4.2542E-1	-4.4373E-1	-7.9857E-2	-2.4601E+0
-8.5510E-1	-8.6548E-1	-1.6101E-1	-4.7983E+0
-9.9884E-1	-9.9762E-1	-1.8816E-1	-5.5309E+0
-8.0902E-1	-7.9590E-1	-1.5231E-1	-4.4126E+0
-3.4821E-1	-3.2867E-1	-6.5274E-2	-1.8222E+0
2.2827E-1	2.4902E-1	4.3602E-2	1.3806E+0
7.2906E-1	7.4371E-1	1.3818E-1	4.1233E+0
9.8633E-1	9.8969E-1	1.8677E-1	5.4870E+0
9.1400E-1	9.0515E-1	1.7311E-1	5.0183E+0
5.3619E-1	5.1788E-1	1.0176E-1	2.8712E+0
-2.0752E-2	-4.1199E-2	-3.4299E-3	-2.2841E-1
-5.6976E-1	-5.8716E-1	-1.0712E-1	-3.2553E+0
-9.2926E-1	-9.3689E-1	-1.7502E-1	-5.1943E+0
-9.7717E-1	-9.7321E-1	-1.8406E-1	-5.3956E+0
-6.9977E-1	-6.8390E-1	-1.3167E-1	-3.7916E+0
-1.8768E-1	-1.6602E-1	-3.4957E-2	-9.2042E-1
3.8788E-1	4.0680E-1	7.3746E-2	2.2554E+0
8.3221E-1	8.4503E-1	1.5767E-1	4.6850E+0
1.0001E+0	1.0004E+0	1.8937E-1	5.5462E+0
8.3374E-1	8.2184E-1	1.5795E-1	4.5564E+0
3.8788E-1	3.6835E-1	7.3746E-2	2.0422E+0
-1.8707E-1	-2.0752E-1	-3.4842E-2	-1.1505E+0
-6.9916E-1	-7.1411E-1	-1.3156E-1	-3.9591E+0
-9.7778E-1	-9.8206E-1	-1.8418E-1	-5.4447E+0
-9.2926E-1	-9.2163E-1	-1.7502E-1	-5.1097E+0
-5.7037E-1	-5.5267E-1	-1.0723E-1	-3.0641E+0
-2.0752E-2	6.1035E-4	-3.4299E-3	3.3839E-3
5.3619E-1	5.5328E-1	1.0176E-1	3.0675E+0
9.1370E-1	9.2224E-1	1.7305E-1	5.1130E+0
9.8633E-1	9.8297E-1	1.8677E-1	5.4497E+0
7.2937E-1	7.1472E-1	1.3824E-1	3.9625E+0
2.2858E-1	2.0782E-1	4.3660E-2	1.1522E+0
-3.4821E-1	-3.6835E-1	-6.5274E-2	-2.0422E+0
-8.0902E-1	-8.2092E-1	-1.5231E-1	-4.5513E+0
-9.9884E-1	-9.9915E-1	-1.8816E-1	-5.5394E+0
-8.5449E-1	-8.4381E-1	-1.6089E-1	-4.6782E+0
-4.2511E-1	-4.0649E-1	-7.9799E-2	-2.2537E+0
1.4679E-1	1.6724E-1	2.8213E-2	9.2718E-1
6.6956E-1	6.8451E-1	1.2695E-1	3.7950E+0
9.6924E-1	9.7382E-1	1.8354E-1	5.3990E+0
9.4482E-1	9.3781E-1	1.7893E-1	5.1993E+0
6.0486E-1	5.8746E-1	1.1473E-1	3.2570E+0
6.3477E-2	4.2419E-2	1.2478E-2	2.3518E-1
-4.9896E-1	-5.1727E-1	-9.3747E-2	-2.8678E+0
-8.9508E-1	-9.0424E-1	-1.6856E-1	-5.0132E+0
-9.9243E-1	-9.8907E-1	-1.8695E-1	-5.4836E+0
-7.5653E-1	-7.4310E-1	-1.4239E-1	-4.1199E+0
-2.6825E-1	-2.4872E-1	-5.0174E-2	-1.3789E+0
3.0945E-1	3.2959E-1	5.8933E-2	1.8273E+0
7.8339E-1	7.9651E-1	1.4844E-1	4.4160E+0
9.9701E-1	9.9792E-1	1.8879E-1	5.5326E+0
8.7616E-1	8.6578E-1	1.6597E-1	4.8000E+0
4.6326E-1	4.4464E-1	8.7983E-2	2.4652E+0
-1.0406E-1	-1.2482E-1	-1.9165E-2	-6.9200E-1
-6.3690E-1	-6.5308E-1	-1.1980E-1	-3.6208E+0
-9.5673E-1	-9.6252E-1	-1.8020E-1	-5.3364E+0
-9.5673E-1	-9.5062E-1	-1.8020E-1	-5.2704E+0
-6.3721E-1	-6.2073E-1	-1.1986E-1	-3.4414E+0
-1.0437E-1	-8.3313E-2	-1.9222E-2	-4.6190E-1
4.6356E-1	4.8218E-1	8.8040E-2	2.6733E+0
8.7646E-1	8.8684E-1	1.6602E-1	4.9168E+0
9.9670E-1	9.9487E-1	1.8873E-1	5.5157E+0
7.8400E-1	7.7118E-1	1.4856E-1	4.2755E+0
3.0914E-1	2.8931E-1	5.8876E-2	1.6040E+0
-2.6886E-1	-2.8870E-1	-5.0289E-2	-1.6006E+0
-7.5653E-1	-7.7026E-1	-1.4239E-1	-4.2705E+0
-9.9243E-1	-9.9365E-1	-1.8695E-1	-5.5090E+0
-8.9508E-1	-8.8593E-1	-1.6856E-1	-4.9117E+0
-4.9927E-1	-4.8187E-1	-9.3805E-2	-2.6716E+0
6.3477E-2	8.4229E-2	1.2478E-2	4.6698E-1
6.0516E-1	6.2073E-1	1.1478E-1	3.4414E+0
9.4482E-1	9.5093E-1	1.7893E-1	5.2721E+0
9.6863E-1	9.6344E-1	1.8343E-1	5.3415E+0
6.6956E-1	6.5369E-1	1.2695E-1	3.6241E+0
1.4648E-1	1.2573E-1	2.8155E-2	6.9708E-1
-4.2572E-1	-4.4342E-1	-7.9914E-2	-2.4584E+0
-8.5480E-1	-8.6548E-1	-1.6095E-1	-4.7983E+0
-9.9854E-1	-9.9762E-1	-1.8810E-1	-5.5309E+0
-8.0872E-1	-7.9620E-1	-1.5225E-1	-4.4143E+0
-3.4821E-1	-3.2837E-1	-6.5274E-2	-1.8205E+0
2.2827E-1	2.4841E-1	4.3602E-2	1.3772E+0
7.2998E-1	7.4371E-1	1.3836E-1	4.1233E+0
9.8663E-1	9.8969E-1	1.8683E-1	5.4870E+0
9.1400E-1	9.0485E-1	1.7311E-1	5.0166E+0
5.3589E-1	5.1758E-1	1.0170E-1	2.8695E+0
-2.0447E-2	-4.1199E-2	-3.3722E-3	-2.2841E-1
-5.7037E-1	-5.8777E-1	-1.0723E-1	-3.2587E+0
-9.2987E-1	-9.3597E-1	-1.7513E-1	-5.1892E+0
-9.7809E-1	-9.7321E-1	-1.8424E-1	-5.3956E+0
-6.9946E-1	-6.8451E-1	-1.3161E-1	-3.7950E+0
-1.8677E-1	-1.6663E-1	-3.4784E-2	-9.2380E-1
3.8757E-1	4.0741E-1	7.3689E-2	2.2587E+0
8.3282E-1	8.4442E-1	1.5778E-1	4.6816E+0
1.0004E+0	9.9915E-1	1.8942E-1	5.5394E+0
8.3282E-1	8.2184E-1	1.5778E-1	4.5564E+0
3.8788E-1	3.6774E-1	7.3746E-2	2.0388E+0
-1.8738E-1	-2.0752E-1	-3.4900E-2	-1.1505E+0
-6.9946E-1	-7.1381E-1	-1.3161E-1	-3.9574E+0
-9.7778E-1	-9.8175E-1	-1.8418E-1	-5.4430E+0
-9.2957E-1	-9.2133E-1	-1.7507E-1	-5.1080E+0
-5.7007E-1	-5.5237E-1	-1.0718E-1	-3.0624E+0
-2.0447E-2	0.0000E+0	-3.3722E-3	0.0000E+0
5.3680E-1	5.5359E-1	1.0187E-1	3.0692E+0
9.1400E-1	9.2194E-1	1.7311E-1	5.1113E+0
9.8602E-1	9.8328E-1	1.8671E-1	5.4514E+0
7.2968E-1	7.1472E-1	1.3830E-1	3.9625E+0
2.2858E-1	2.0844E-1	4.3660E-2	1.1556E+0
-3.4760E-1	-3.6774E-1	-6.5159E-2	-2.0388E+0
-8.0872E-1	-8.2062E-1	-1.5225E-1	-4.5496E+0
-9.9884E-1	-9.9915E-1	-1.8816E-1	-5.5394E+0
-8.5449E-1	-8.4412E-1	-1.6089E-1	-4.6799E+0
-4.2542E-1	-4.0619E-1	-7.9857E-2	-2.2520E+0
1.4679E-1	1.6693E-1	2.8213E-2	9.2549E-1
6.6956E-1	6.8481E-1	1.2695E-1	3.7967E+0
9.6893E-1	9.7412E-1	1.8349E-1	5.4007E+0
9.4452E-1	9.3750E-1	1.7888E-1	5.1976E+0
6.0486E-1	5.8807E-1	1.1473E-1	3.2604E+0
6.3477E-2	4.2114E-2	1.2478E-2	2.3349E-1
-4.9988E-1	-5.1727E-1	-9.3920E-2	-2.8678E+0
-8.9508E-1	-9.0393E-1	-1.6856E-1	-5.0115E+0
-9.9182E-1	-9.8938E-1	-1.8683E-1	-5.4853E+0
-7.5714E-1	-7.4249E-1	-1.4251E-1	-4.1165E+0
-2.6855E-1	-2.4841E-1	-5.0231E-2	-1.3772E+0
-2.0752E-2	-2.1057E-2	-3.4299E-3	-1.1674E-1
-2.0752E-2	-2.0752E-2	-3.4299E-3	-1.1505E-1
-2.1057E-2	-2.0447E-2	-3.4875E-3	-1.1336E-1
-2.0752E-2	-2.1057E-2	-3.4299E-3	-1.1674E-1
-2.0752E-2	-2.0447E-2	-3.4299E-3	-1.1336E-1
-2.1057E-2	-2.0752E-2	-3.4875E-3	-1.1505E-1
-2.0752E-2	-2.0752E-2	-3.4299E-3	-1.1505E-1
-2.0447E-2	-2.0752E-2	-3.3722E-3	-1.1505E-1
-2.0447E-2	-2.1057E-2	-3.3722E-3	-1.1674E-1
-2.1362E-2	-2.0752E-2	-3.5451E-3	-1.1505E-1
-2.0752E-2	-2.0752E-2	-3.4299E-3	-1.1505E-1
-2.0447E-2	-2.1057E-2	-3.3722E-3	-1.1674E-1
-2.0447E-2	-2.0447E-2	-3.3722E-3	-1.1336E-1
-2.0752E-2	-2.1057E-2	-3.4299E-3	-1.1674E-1
-2.0447E-2	-2.0752E-2	-3.3722E-3	-1.1505E-1
-2.0752E-2	-2.0447E-2	-3.4299E-3	-1.1336E-1
-2.0447E-2	-2.0447E-2	-3.3722E-3	-1.1336E-1
-2.0447E-2	-2.0752E-2	-3.3722E-3	-1.1505E-1
-2.0752E-2	-2.0752E-2	-3.4299E-3	-1.1505E-1
-2.0752E-2	-2.0447E-2	-3.4299E-3	-1.1336E-1
-2.0752E-2	-2.0752E-2	-3.4299E-3	-1.1505E-1
-2.0447E-2	-2.0752E-2	-3.3722E-3	-1.1505E-1
-2.0142E-2	-2.0447E-2	-3.3146E-3	-1.1336E-1
-2.1057E-2	-2.0447E-2	-3.4875E-3	-1.1336E-1
-2.0752E-2	-2.0752E-2	-3.4299E-3	-1.1505E-1
-2.1362E-2	-2.0447E-2	-3.5451E-3	-1.1336E-1
-2.0752E-2	-2.0752E-2	-3.4299E-3	-1.1505E-1
-2.1057E-2	-2.0752E-2	-3.4875E-3	-1.1505E-1
-2.0752E-2	-2.0142E-2	-3.4299E-3	-1.1167E-1
-2.0447E-2	-2.0752E-2	-3.3722E-3	-1.1505E-1
-2.0752E-2	-2.0447E-2	-3.4299E-3	-1.1336E-1
-2.0752E-2	-2.1057E-2	-3.4299E-3	-1.1674E-1
-2.0447E-2	-2.1057E-2	-3.3722E-3	-1.1674E-1
-2.1057E-2	-2.0752E-2	-3.4875E-3	-1.1505E-1
-2.0447E-2	-2.1057E-2	-3.3722E-3	-1.1674E-1
-2.1057E-2	-2.0447E-2	-3.4875E-3	-1.1336E-1
-2.0752E-2	-2.0752E-2	-3.4299E-3	-1.1505E-1
-2.0752E-2	-2.1057E-2	-3.4299E-3	-1.1674E-1
-2.0447E-2	-2.0752E-2	-3.3722E-3	-1.1505E-1
-2.0447E-2	-2.0447E-2	-3.3722E-3	-1.1336E-1
-2.0447E-2	-2.0447E-2	-3.3722E-3	-1.1336E-1
-2.0447E-2	-2.1057E-2	-3.3722E-3	-1.1674E-1
-2.0447E-2	-2.0447E-2	-3.3722E-3	-1.1336E-1
-2.0447E-2	-2.1057E-2	-3.3722E-3	-1.1674E-1
-2.0142E-2	-2.0752E-2	-3.3146E-3	-1.1505E-1
-2.0142E-2	-2.0752E-2	-3.3146E-3	-1.1505E-1
-2.0752E-2	-2.0447E-2	-3.4299E-3	-1.1336E-1
-2.1057E-2	-2.0752E-2	-3.4875E-3	-1.1505E-1
-2.1057E-2	-2.0752E-2	-3.4875E-3	-1.1505E-1
-2.0447E-2	-2.0752E-2	-3.3722E-3	-1.1505E-1
-2.0142E-2	-2.0447E-2	-3.3146E-3	-1.1336E-1
-2.0752E-2	-2.0447E-2	-3.4299E-3	-1.1336E-1
-2.0447E-2	-2.0447E-2	-3.3722E-3	-1.1336E-1
-2.1057E-2	-2.0447E-2	-3.4875E-3	-1.1336E-1
-2.0752E-2	-2.0447E-2	-3.4299E-3	-1.1336E-1
-2.0447E-2	-2.0752E-2	-3.3722E-3	-1.1505E-1
-2.0752E-2	-2.0752E-2	-3.4299E-3	-1.1505E-1
-2.1057E-2	-2.1057E-2	-3.4875E-3	-1.1674E-1
-2.0752E-2	-2.0447E-2	-3.4299E-3	-1.1336E-1
-2.0752E-2	-2.0447E-2	-3.4299E-3	-1.1336E-1
-2.0752E-2	-2.0752E-2	-3.4299E-3	-1.1505E-1
-2.0447E-2	-2.0447E-2	-3.3722E-3	-1.1336E-1
-2.0752E-2	-2.0447E-2	-3.4299E-3	-1.1336E-1
-2.0752E-2	-2.0752E-2	-3.4299E-3	-1.1505E-1
-2.1057E-2	-2.0752E-2	-3.4875E-3	-1.1505E-1
-2.0752E-2	-2.0447E-2	-3.4299E-3	-1.1336E-1
-2.0752E-2	-2.0447E-2	-3.4299E-3	-1.1336E-1
-2.0752E-2	-2.0447E-2	-3.4299E-3	-1.1336E-1
-2.0752E-2	-2.0752E-2	-3.4299E-3	-1.1505E-1
-2.0752E-2	-2.0752E-2	-3.4299E-3	-1.1505E-1
-2.0142E-2	-2.0752E-2	-3.3146E-3	-1.1505E-1
-2.1057E-2	-2.0752E-2	-3.4875E-3	-1.1505E-1
-2.0752E-2	-2.0142E-2	-3.4299E-3	-1.1167E-1
-2.0447E-2	-2.0752E-2	-3.3722E-3	-1.1505E-1
-2.0142E-2	-2.0752E-2	-3.3146E-3	-1.1505E-1
-2.0447E-2	-2.0752E-2	-3.3722E-3	-1.1505E-1
-2.1057E-2	-2.0752E-2	-3.4875E-3	-1.1505E-1
-2.0752E-2	-2.0142E-2	-3.4299E-3	-1.1167E-1
-2.0752E-2	-2.0752E-2	-3.4299E-3	-1.1505E-1
-2.1057E-2	-2.0752E-2	-3.4875E-3	-1.1505E-1
-2.0447E-2	-2.0447E-2	-3.3722E-3	-1.1336E-1
-2.1057E-2	-2.1057E-2	-3.4875E-3	-1.1674E-1
-2.0142E-2	-2.0142E-2	-3.3146E-3	-1.1167E-1
-2.0752E-2	-2.0447E-2	-3.4299E-3	-1.1336E-1
-2.1057E-2	-2.0752E-2	-3.4875E-3	-1.1505E-1
-2.0447E-2	-2.0447E-2	-3.3722E-3	-1.1336E-1
-2.0447E-2	-2.0447E-2	-3.3722E-3	-1.1336E-1
-2.0752E-2	-2.0142E-2	-3.4299E-3	-1.1167E-1
-2.0447E-2	-2.1057E-2	-3.3722E-3	-1.1674E-1
-2.0752E-2	-2.0752E-2	-3.4299E-3	-1.1505E-1
-2.1057E-2	-2.0752E-2	-3.4875E-3	-1.1505E-1
-2.0447E-2	-2.1362E-2	-3.3722E-3	-1.1844E-1
-2.0447E-2	-2.0752E-2	-3.3722E-3	-1.1505E-1
-2.1057E-2	-2.0752E-2	-3.4875E-3	-1.1505E-1
-2.1057E-2	-2.0752E-2	-3.4875E-3	-1.1505E-1
-2.0752E-2	-2.0752E-2	-3.4299E-3	-1.1505E-1
-2.0447E-2	-2.0447E-2	-3.3722E-3	-1.1336E-1
-2.0752E-2	-2.0752E-2	-3.4299E-3	-1.1505E-1
-2.0447E-2	-2.0142E-2	-3.3722E-3	-1.1167E-1
-2.0447E-2	-2.0752E-2	-3.3722E-3	-1.1505E-1
-2.0752E-2	-2.0752E-2	-3.4299E-3	-1.1505E-1
-2.0142E-2	-2.0142E-2	-3.3146E-3	-1.1167E-1
-2.0142E-2	-2.0752E-2	-3.3146E-3	-1.1505E-1
-2.1057E-2	-2.0752E-2	-3.4875E-3	-1.1505E-1
-2.0752E-2	-2.1362E-2	-3.4299E-3	-1.1844E-1
-2.0752E-2	-2.0752E-2	-3.4299E-3	-1.1505E-1
-2.0447E-2	-2.0752E-2	-3.3722E-3	-1.1505E-1
-2.0142E-2	-2.0142E-2	-3.3146E-3	-1.1167E-1